Workbook
Name Khmer_Lunar_2025: _xlfn.LAMBDA(_xlpm.X,VLOOKUP(_xlpm.X,Khmer_Lunar_Table,2,FALSE))
Name Khmer_Lunar_Table: Khmer_Lunar_2025!$AI$2:$AJ$367

Sheet FILE #
A1: suvannaphum
A2: =VLOOKUP($B$4,DATA!A3:AH4999,4,FALSE)&" CLEARANCE WORKSHEET" -> IMPORT CLEARANCE WORKSHEET
A4: REF No: | B4: 25207 | C4: SHIPMENT MODE: | D4: =VLOOKUP($B$4,DATA!A3:AH4999,5,FALSE) -> SEA-FCL | G4: =VLOOKUP($B$4,DATA!$A$3:$AH$4999,2,FALSE)&", "&G12&" , "&H12&" , "&I12&" , "&J12 -> TH25080681, , , , | O4: 44438 | P4: 44480 | Q4: =P4-O4 -> 42 | R4: =Q4*6.6 -> 277.2
A5: REC DATE: | B5: =VLOOKUP($B$4,DATA!$A$3:$AH$4999,34,FALSE) -> 45902 | C5: VIA: | D5: =VLOOKUP($B$4,DATA!$A$3:$AH$4999,20,FALSE) -> SHV11 | G5: 1 | H5: 2 | I5: 3 | J5: 4 | K5: 5
G6: =$B$4&""&G5 -> 252071 | H6: =IFERROR($B$4&""&H5,"") -> 252072 | I6: =$B$4&""&I5 -> 252073 | J6: =$B$4&""&J5 -> 252074 | K6: =$B$4&""&K5 -> 252075
A7: SHIPPER: | B7: =VLOOKUP($B$4,DATA!$A$3:$AH$4999,33,FALSE)&" "&G7&" "&H7&" "&I7&" "&J7&" "&K7&"" -> C. PLUS STEEL | C7: ADDRESS: | D7: =VLOOKUP($B$4,DATA!$A$3:$AH$4999,19,FALSE) -> TH | G7: =IFERROR(VLOOKUP(G6,DATA!$A$3:$AH$4999,33,FALSE),"") | H7: =IFERROR(VLOOKUP(H6,DATA!$A$3:$AH$4999,33,FALSE),"") | I7: =IFERROR(VLOOKUP(I6,DATA!$A$3:$AH$4999,33,FALSE),"") | J7: =IFERROR(VLOOKUP(J6,DATA!$A$3:$AH$4999,33,FALSE),"") | K7: =IFERROR(VLOOKUP(K6,DATA!$A$3:$AH$4999,33,FALSE),"")
A8: CONSIGNEE: | B8: =VLOOKUP($B$4,DATA!$A$3:$AH$4999,6,FALSE) -> OISHI F&B (CAMBODIA) CO.,LTD | C8: ADDRESS: | D8: PNH
B9: =VLOOKUP($B$4,DATA!$A$3:$AH$4999,19,FALSE) -> TH | C9: TO: | D9: =VLOOKUP($B$4,DATA!$A$3:$AH$4999,22,FALSE) -> SISEZ | E9: VIA: | F9: =VLOOKUP($B$4,DATA!$A$3:$AH$4999,20,FALSE) -> SHV11
A10: ARRIVAL DATE: | B10: =VLOOKUP($B$4,DATA!$A$3:$AH$4999,17,FALSE) -> 45900 | C10: IMPORT CC DATE:
A11: DELIVERY DATE:
A12: BL No.: | B12: =VLOOKUP($B$4,DATA!$A$3:$AH$4999,2,FALSE)&" "&G12&" "&H12&" "&I12&" "&J12&" "&K12 -> TH25080681 | C12: INV/PKL: | D12: =VLOOKUP($B$4,DATA!$A$3:$AH$4999,8,FALSE) -> 139_2567 | G12: =IFERROR(VLOOKUP(G6,DATA!$A$3:$AH$4999,2,FALSE),"") | H12: =IFERROR(VLOOKUP(H6,DATA!$A$3:$AH$4999,2,FALSE),"") | I12: =IFERROR(VLOOKUP(I6,DATA!$A$3:$AH$4999,2,FALSE),"") | J12: =IFERROR(VLOOKUP(J6,DATA!$A$3:$AH$4999,2,FALSE),"") | K12: =IFERROR(VLOOKUP(K6,DATA!$A$3:$AH$4999,2,FALSE),"")
A13: CONTAINER No.: | B13: =VLOOKUP($B$4,DATA!$A$3:$AH$4999,28,FALSE)&" "&G13&" " &H13&" " &I13&" " &J13&" " &K13 -> 1.FFAU4696414-40HC, 2.NBYU9027180-40HC, 3.NBYU8114320-40HC, 4.NBYU8158334-40HC, 5.NBYU8170200-40HC | C13: SEAL No.: | G13: =IFERROR(VLOOKUP(G6,DATA!$A$3:$AH$4999,28,FALSE),"") | H13: =IFERROR(VLOOKUP(H6,DATA!$A$3:$AH$4999,28,FALSE),"") | I13: =IFERROR(VLOOKUP(I6,DATA!$A$3:$AH$4999,28,FALSE),"") | J13: =IFERROR(VLOOKUP(J6,DATA!$A$3:$AH$4999,28,FALSE),"") | K13: =IFERROR(VLOOKUP(K6,DATA!$A$3:$AH$4999,28,FALSE),"")
A14: VOLUME: | B14: =VLOOKUP($B$4,DATA!$A$3:$AH$4999,30,FALSE)&"x20', "&VLOOKUP($B$4,DATA!$A$3:$AH$4999,31,FALSE)&"x40'" -> 0x20', 5x40' | C14: VSSL NAME: | D14: =VLOOKUP($B$4,DATA!$A$3:$AH$4999,16,FALSE) -> XIN MING ZHOU 98 V.2511S
A15: TRUCK No.: | C15: COMMODITY: | D15: =VLOOKUP($B$4,DATA!$A$3:$AH$4999,23,FALSE)&", "&VLOOKUP($B$4,DATA!$A$3:$AH$4999,29,FALSE)&" "&G15&" "&H15&" "&I15 -> UTILITY PIPING SUPPLY FOR MACHINERY, MEP WORKS MATERIAL, 76 PACKAGES | G15: =IFERROR(VLOOKUP(G6,DATA!$A$3:$AH$4999,23,FALSE)&", "&VLOOKUP(G6,DATA!$A$3:$AH$4999,29,FALSE),"") | H15: =IFERROR(VLOOKUP(H6,DATA!$A$3:$AH$4999,23,FALSE)&", "&VLOOKUP(H6,DATA!$A$3:$AH$4999,29,FALSE),"") | I15: =IFERROR(VLOOKUP(I6,DATA!$A$3:$AH$4999,23,FALSE)&", "&VLOOKUP(I6,DATA!$A$3:$AH$4999,29,FALSE),"") | J15: =IFERROR(VLOOKUP(J6,DATA!$A$3:$AH$4999,23,FALSE)&", "&VLOOKUP(J6,DATA!$A$3:$AH$4999,29,FALSE),"") | K15: =IFERROR(VLOOKUP(K6,DATA!$A$3:$AH$4999,23,FALSE)&", "&VLOOKUP(K6,DATA!$A$3:$AH$4999,29,FALSE),"")
C17: SERVICE PROVIDE: | D17: =VLOOKUP($B$4,DATA!$A$3:$AH$4999,35,FALSE) -> #REF!
A19: Remark:

Sheet DATA
A1: SHIPMENT INFORMATION | C1: 3 | D1: 4 | E1: 5 | F1: 6 | G1: 7 | H1: 8 | I1: 9 | J1: 10 | K1: 11 | L1: 12 | M1: 13 | N1: 14 | O1: 15 | P1: 16 | Q1: 17 | R1: 18 | S1: 19 | T1: 20 | U1: 21 | V1: 22 | W1: 23 | X1: 24 | Y1: 25 | Z1: 26 | AA1: 27 | AB1: 28 | AC1: 29 | AD1: 30 | AE1: 31 | AF1: 32 | AG1: 33 | AH1: 34 | AI1: 35 | AJ1: ACTIVITIES
A2: Job | B2: B/L No | C2: B/L Date | D2: Imp/Exp | E2: Ship'm Mode | F2: Importer | G2: Client Name | H2: Inv | I2: PKL | J2: INV & PKL Date | K2: CO | L2: CO Date | M2: Rcv Date | N2: Shipping Line | O2: MBL # | P2: Vssl/Truck | Q2: ETA/ETD | R2: LOAD ON | S2: POL | T2: Transit Port | U2: SCAN STATION | V2: Final Destination | W2: Commodity | X2: NW | Y2: GW | Z2: CBM/CIF | AA2: FOB | AB2: Container No | AC2: Quantity | AD2: 20' | AE2: 40' | AF2: CONT SIZE | AG2: Shipper Name | AH2: Received Date | AI2: SR NAME | AJ2: TP | AK2: TP DATE | AL2: IM8 | AM2: IM8 DATE | AN2: GATE IN DP/BW/SEZ | AO2: IM7 | AP2: IM7 DATE | AQ2: SR | AR2: SR DATE | AS2: CV | AT2: CV DATE | AU2: CO | AV2: CO DATE | AW2: IM4 | AX2: IM4 DATE | AY2: EX3 | AZ2: EX3 DATE | BA2: GATE OUT DP/BW/SEZ | BB2: INV
A3: 060 | B3: EH19/0702 | D3: IMPORT | E3: Land | F3: Big C | H3: INV-SG01082562 | I3: EH19/0702 | M3: 43706 | R3: 43690 | S3: TH | U3: POP | V3: POP | W3: STAINLESS EQUIPMENT & ACC | AC3: 1 LOT = 302 PKGS | AF3: - Apply Permit: 02.09.2019, Received: 08.09.2019, 10.09.2019
A4: 052 | B4: EW19/0071 | D4: IMPORT | E4: Land | F4: Big C | H4: 300719 | I4: 300719 | M4: 43705 | S4: TH | U4: POP | V4: POP | W4: ICE MAKER 624KG/24H, 1000KG/24H, ICE CART, ICED SCOOP | AF4: - Apply Permit: 05.09.2019, Received: 06.09.2019, 06.09.2019
A5: 035 | B5: BKK20190904 | D5: IMPORT | E5: Land | F5: Big C | H5: ML-INV-60260011 | I5: ML-INV-60260011 | S5: TH | U5: POP | V5: POP | W5: SEWAGE PUMP | AF5: - Apply Permit: 04.09.2019, Received: 06.09.2019, 06.09.2019
A6: 061 | B6: TBL0190845 | D6: IMPORT | E6: Land | F6: Big C | H6: INV_HL/Q/19-0901 | I6: PL_HL/Q/19-0901 | R6: 43709 | S6: TH | U6: POP | V6: POP | W6: FRUIT RACK | AC6: 15PKG = 52SET | AF6: - Apply Permit: 02.09.2019, Received: 04.09.2019, 05.09.2019
A7: 057 | B7: EW19/0257 | D7: IMPORT | E7: Land | F7: Big C | H7: 20190801 | I7: 20190801 | M7: 43697 | R7: 43693 | S7: TH | U7: POP | V7: POP | W7: STEEL FIXTURE (GONDOLA) | AB7: EWTU8880009-40HC | AE7: 1 | AF7: - Apply Permit: 30.08.2019, Received: 02.09.2019, 04.09.2019
A8: 053 | B8: TWB1908011 | D8: IMPORT | E8: Land | F8: Big C | H8: IV-2019145 | I8: PL-2019145 | M8: 43706 | S8: TH | U8: POP | V8: POP | W8: EXTERIOR SIGNAGE, INTERIOR SIGNAGE | AF8: - Apply Permit: 05.09.2019, Received: 06.09.2019, 06.09.2019
A9: 062 | B9: M02355 | D9: IMPORT | E9: Land | F9: Big C | G9: MASS | H9: BC2019-002 | I9: BC2019-002 | M9: 43710 | R9: 43709 | S9: TH | U9: POP | V9: POP | W9: PLASTIC BASKET | AC9: 9 ITEM = 262 PKG | AF9: - Apply Permit: 10.09.2019, Received: 17.09.2019, 20.09.2019
A10: 064 | B10: M02402 | D10: IMPORT | E10: Land | F10: Big C | G10: MASS | H10: INV BC2019-003 | I10: INV BC2019-003 | S10: TH | U10: POP | V10: POP | W10: COMPRESSED AIR CYLINDERS 300 BAR FOR SCBA | AC10: 23 ITEMS = 53 PKGS | AF10: - Apply Permit: 16.09.2019, Received: 17.09.2019, 20.09.2019
A11: 063 | B11: GLSW937891 | D11: IMPORT | E11: Sea | F11: BJC | G11: GLS | H11: 20190905/VP-BJC-KH | I11: 20190905/VP-BJC-KH | M11: 43714 | P11: GLS 07 V.937W | Q11: 43724 | R11: 43715 | S11: VN | T11: PNH02 | U11: PNH02 | V11: SISEZ | W11: NPKIN TISSUE PAPER, TOILET TISSUE PAPER | AB11: DRYU9021795-(40') PKEU5026440-(40') SEGU5593994-(40') SEGU5593192-(40') SEGU5592998-(40') | AC11: 135 ROLL | AE11: 5 | AF11: - Apply & Received TP (020/19): 13.09.2019 - Transit Clearance (T459): 17.09.2019 - Delivery from PPAP and arrive at SISEZ (By PPAP): 18.09.2019 - Apply and Received Form D (017/19): 20.09.2019, Valuation (025/19): 20.09.2019 - Complete Clearance (I26): 20.09.2019 | AI11: 063
A12: 065 | B12: GLSW939903 | D12: IMPORT | E12: Sea | F12: BJC | G12: GLS | H12: 20190917/VP-BJC-KH | I12: 20190917/VP-BJC-KH | M12: 43726 | P12: GLS CUU LONG V.939W | Q12: 43744 | R12: 43728 | S12: VN | T12: PNH02 | U12: PNH02 | V12: SISEZ | W12: TOILET TISSUE PAPER | AB12: DRYU9980125-(40') DRYU9955122-(40') | AC12: 72 ROLL | AE12: 2 | AF12: - Apply & Received TP (021/19): 01.10.2019 - Transit Clearance (T480): 02.10.2019 - Delivery from PPAP to SISEZ (By PPAP): 02.10.2019 - Apply and Received Form D (018/19): 18.10.2019, Valuation (026/19): 18.10.2019 - Complete Clearance (I29): 19.10.2019 | AI12: 063
A13: 066 | B13: TW1934XG23/48 | D13: IMPORT | E13: Sea | F13: China Construction Fourth (Mr. Samsen) | H13: 1900820-CT/CCF | I13: 1900820-CT/CCF | M13: 43727 | P13: EVNIA 1931 | Q13: 43734 | R13: 43706 | S13: CN | T13: STH | U13: STH | V13: STH | W13: ALLOY DEFORMED REBAR (STEEL BAR) | AB13: BREAK BULK | AC13: 1117 BUNDLE = 2578.404MT | AF13: - Applied Form E: 02.10.2019 and received (11483): 26.09.2019 - Applied Invoice Valuation: 02.10.2019, Received (54325): 03.10.2019 - Import Clearance at Steung Hav (I395): 17.10.2019
A14: 067 | B14: OMPLCHKHOMP037-19 | D14: IMPORT | E14: Sea | F14: BJC | G14: OMP | H14: 023/2019 | I14: 023/2019 | M14: 43733 | P14: ANU BHUM V.0025S | Q14: 43732 | R14: 43730 | S14: TH | T14: SHV15 | U14: SHV15 | V14: SISEZ | W14: JUMBO ROLL NAPKIN TISSUE | AB14: TRIU9269776-(40') | AC14: 120 ROLL | AE14: 1 | AF14: - Apply & Received TP (022/19): 01.10.2019 - Cleared Transit T13: 02.10.2019, - Delivered from OMP on 06.10.2019 by OMP and arrived at SISEZ: 07.10.2019 -​ Invoice Valuation (030/19): 18.10.2019, Apply Form D (019/19): 18.10.2019 - Clear Imp (I30): 19.10.2019 | AI14: =A14 -> 067
A15: 068 | B15: OMPLCHKHOMP036-19 | D15: IMPORT | E15: Sea | F15: BJC | G15: OMP | H15: 024/2019 | I15: 024/2019 | M15: 43733 | P15: ANU BHUM V.0025S | Q15: 43732 | R15: 43730 | S15: TH | T15: SHV15 | U15: SHV15 | V15: SISEZ | W15: CARTON BOX, PLASTIC WRAPPER, STICKER, BELT, PAPER CORE | AB15: TTNU9518175-(40') | AC15: 24 PLTS | AE15: 1 | AF15: - Reqeusted & Received TP (023/19): 01.10.2019 - Cleared Transit T12 (OMP): 02.10.2019, - Delivered from OMP on 06.10.2019 by OMP and arrived at SISEZ: 07.10.2019 -​ Invoice Valuation (027/19): 18.10.2019 - Clear Imp (I27): 18.10.2019 | AI15: =A15 -> 068 | AJ15: 023/19 | AL15: T12 | AM15: 43740
A16: 069 | B16: TW1934XG25 | D16: IMPORT | E16: Sea | F16: Royal CCT PLC (Mr. Samsen) | H16: 1900920-CT/ZT | I16: 1900920-CT/ZT | M16: 43739 | P16: T/B RATTANAWANICH 4 | S16: CN | T16: STH | U16: STH | V16: STH | W16: ALLOY DEFORMED REBAR (STEEL BAR) | AB16: BREAK BULK | AC16: 2051 BD = 4693.222MT | AF16: - Applied Form E: 24.10.2019 and received (12769): 25.09.2019 - Applied Invoice Valuation: 28.10.2019, Received (59957): 30.10.2019 - Import Clearance at Steung Hav (I416): 08.11.2019
A17: 070 | B17: TW1934XG24 | D17: IMPORT | E17: Sea | F17: Shang Tang Investment Co., Ltd (Mr. Samsen) | H17: 1900920-CT/ST | I17: 1900920-CT/ST | M17: 43739 | P17: T/B RATTANAWANICH 4 | S17: CN | T17: STH | U17: STH | V17: STH | W17: ALLOY DEFORMED REBAR (STEEL BAR) | AB17: BREAK BULK | AC17: 435 BD = 1008.330MT | AF17: - Apply New Importer and Asycuda: 25.10.2019 and Received: 25.10.2019 - Applied Form E: 24.10.2019 and received (12777): 25.09.2019 - Applied Invoice Valuation: 28.10.2019, Received (59955): 30.10.2019 - Import Clearance at Steung Hav (I409): 30.10.2019
A18: 071 | B18: GLSW943932 | D18: IMPORT | E18: Sea | F18: BJC | G18: GLS | H18: 20191016/VP-BJC-KH | I18: 20191016/VP-BJC-KH | M18: 43760 | Q18: 43764 | S18: VN | T18: PNH02 | U18: PNH02 | V18: SISEZ | W18: NAPKIN TISSUE PAPER | AB18: GAOU6458563-40HC, GAOU6458563-40HC | AC18: 72 ROLL | AE18: 2 | AF18: - Apply & Received TP (026/19): 28.10.2019 - Transit Clearance (T546): 30.10.2019 - Delivery from PPAP and arrive at SISEZ (By PPAP): 30.10.2019 - Apply and Received Form D (020/19) & Valuation (030/19): 25.10.2019 - Complete Clearance (I32): 25.11.2019 | AI18: =A18 -> 071 | AL18: 13800000 | AS18: 43787
A19: 072 | B19: 7762 6825 0576 | D19: IMPORT | E19: Air-LCL | F19: BJC | G19: BJC | H19: 9197700031 | I19: 847986 | M19: 43741 | O19: 618-72653136 | S19: CN | T19: PNH01 | U19: PNH01 | V19: SISEZ | W19: PIN, WHEEL, PIN, BUSHING, CROWNED PULLEY D = 100MM | AB19: LCL | AC19: 12 PCS | AF19: - Apply and Received TP (024/19): 04.10.2019 - Transit Clearance (T5601): 07.10.2019 - Delivered from PNH AIRPORT and arrived SISEZ: 07.10.2019 - Apply & Received Invoice Valuation (028/19): 18.10.2019 - Import Clearance (I31): 19.10.2019 | AI19: =A19 -> 072
A20: 073 | B20: OMPLCHKHOMP044/19 | D20: IMPORT | E20: Sea | F20: BJC | G20: OMP | H20: 026/2019 | I20: 026/2019 | M20: 43746 | Q20: 43745 | S20: TH | T20: SHV15 | U20: SHV15 | V20: SISEZ | W20: CARTON BOX, PLASTIC WRAPPER, STICKER, PAPER CORE | AB20: TCKU9303523-40HC, TTNU9660301-40HC | AC20: 49 PLT | AE20: 2 | AF20: - Reqeusted TP (OMP-SISEZ) & Received (025/19): 08.10.2019 - Cleared Transit T14 (OMP): 11.10.2019, - Delivered from OMP on 10.2019 by OMP and arrived at SISEZ: 10.2019 -Invoice Valuation (029/19): 18.10.2019 - Clear Imp (I28): 18.10.2019 | AI20: =A20 -> 073
A21: 074 | B21: GLSW946955 | D21: IMPORT | E21: sea | F21: BJC | G21: GLS | H21: 20191105/VP-BJC-KH | I21: 20191105/VP-BJC-KH | M21: 43774 | N21: GLS | Q21: 43794 | S21: VN | T21: PNH02 | U21: PNH02 | V21: SISEZ | W21: NAPKIN TISSUE PAPER | AB21: DRYU9950455-40HC, DRYU9955122-40HC, DRYU9970410-40HC | AC21: 108 ROLL | AE21: 3 | AF21: - Apply & Received Transit Permit (028/19): 25.11.2019 - Transit Clearance (T610): 26.11.2019 - Delivery from PPAP to SISEZ (By PPAP): 27.11.2019 - Apply & Received Form D (023/19): 04.12.2019, Valuation (034/19): 04.12.2019 - Complete Clearance (I37): 04.12.2019 | AI21: =A21 -> 074
A22: 075 | B22: OMPLCHKHOMP053/19 | D22: IMPORT | E22: Sea | F22: BJC | G22: OMP | H22: 028/2019 | I22: 028/2019 | M22: 43775 | N22: OMP | Q22: 43775 | S22: TH | T22: SHV15 | U22: SHV15 | V22: SISEZ | W22: JUMBO ROLL NAPKIN TISSUE | AB22: OMPL9002014-40HC, OMPL9055698-40HC | AC22: 155 ROLL | AE22: 2 | AF22: - Reqeusted & Received TP (026/19): 14.11.2019 - Cleared Transit (T15): 15.11.2019, - Delivered from OMP on 17.11.2019 by OMP and arrived at SISEZ: 18.11.2019 - Apply & Received Invoice Valuation (032/19): 25.11.2019, Form D (021/19): 25.11.2019 - Clear Imp (I33 ): 25.11.20192 | AI22: =A22 -> 075 | AJ22: 027/19 | AL22: T15 | AM22: 43784 | AS22: 43787
A23: 076 | B23: XDIC000321 | D23: IMPORT | E23: Sea | F23: GREAT WALL (FULL WELL) | G23: CMA | M23: 43774 | N23: CMA | P23: TOKYO TOWER V.0077.010 | Q23: 43753 | S23: CN | U23: SHV01 | V23: SIDP | W23: FAW CAR | AB23: UESU5180963-40HC | AC23: 2 UNITS | AE23: 1 | AF23: - Applied TP (SHV-SIDP): 06.11.2019, Received (04132អគរ.រគ): 08.11.2019, 08.11.2019 | AL23: Reimbursement | AS23: not yet get money
A24: 077 | B24: ONEYDXBV07167900 | D24: IMPORT | E24: Sea | F24: YAT SOVANN (FULL WELL) | G24: ONE | M24: 43785 | N24: ONE | P24: BRIDGE V.0092N | Q24: 43730 | S24: JEBEL ALI | U24: SHV01 | V24: SIDP | W24: ROLLS ROYCE | AB24: AMFU8745626-40HC | AC24: 1 UNIT | AE24: 1 | AF24: - Applied TP (SHV-SIDP): 18.11.2019, Received (04257អគរ.រគ): 18.11.2019, 19.11.2019
A25: 078 | B25: GLSW947971 | D25: IMPORT | E25: Sea | F25: BJC | G25: GLS | H25: 20191114/VP-BJC-KH | I25: 20191114/VP-BJC-KH | M25: 43790 | N25: GLS | Q25: 43794 | S25: VN | T25: PNH02 | U25: PNH02 | V25: SISEZ | W25: NAPKIN TISSUE PAPER, TOILET TISSUE PAPER | AB25: DRYU9954759-40HC, DRYU9972602 -40HC | AC25: 42 ROLL | AE25: 2 | AF25: - Apply & Received Transit Permit (029/19): 25.11.2019 - Transit Clearance (T611): 26.11.2019 - Delivery from PPAP to SISEZ (By PPAP): 28.11.2019 - Apply & Received Form D (022/19): 04.12.2019, Valuation (033/19): 04.12.2019 - Complete Clearance (I36): 04.12.2019 | AI25: =A25 -> 078
A26: 079 | B26: SHAWD059070 | C26: 43787 | D26: IMPORT | E26: Sea | F26: TF MOTORS (CAMBODIA) CO., LTD | G26: SHENDA | H26: CAM20190912N | I26: CAM20190912N | M26: 43799 | N26: IAL | Q26: 43804 | S26: CN | T26: PNH02 | U26: PNH02 | V26: SIBW | W26: NEW CAR | AB26: IAAU1726760 (40'), TCNU4203824 (40') | AC26: 5 UNITS | AE26: 2 | AF26: - Request TP (PPAP-SIBW): 06.12.2019, Received (04518អគរ): 07.12.2019 - Request TP (SIBW-MG Showroom): 06.12.2019, Received (SDR): 10.12.2019 - Transit Clearance T632 (IM8: PPAP-SIBW): 09.12.2019, and deliver and arrive to SIBW: 10.12.2019 - Stock in SIBW I 38 (IM7): 10.12.2019 - Do Clearance I 39 (IM4) for 3 Cars: 16.12.2019 - Do Clearance I41 (IM4) for 2 Care: 25.1.2019
A27: 080 | B27: OMPLCHKHOMP066-19 | D27: IMPORT | E27: Sea | F27: BJC | G27: OMP | H27: 030/2019 | I27: 030/2019 | M27: 43810 | N27: OMP | P27: NP SAMUTSAKHON V.014S | Q27: 43807 | S27: TH | T27: SHV15 | U27: SHV15 | V27: SISEZ | W27: CARTON BOX, PLASTIC WRAPPER, BLADE/STEEL | AB27: TCKU9552470-40HC | AC27: 20 PLTS | AE27: 1 | AF27: - Reqeusted & Received (030/19): 11.12.2019 - Cleared Transit (T16): 12.12.2019, - Delivered from OMP on 12.12.2019 by OMP and arrived at SISEZ: 13.12.2019 - Invoice Valuation (035/19): 23.12.2019 - Clear Imp (I40): 23.12.2019 | AI27: =A27 -> 080
A28: 081 | B28: GLSW951006 | C28: 43813 | D28: IMPORT | E28: Sea | F28: BJC | G28: PPAP | H28: 20191213/VP-BJC-KH | I28: 20191213/VP-BJC-KH | J28: 43812 | K28: VN-KH 19/01/36201 | L28: 43816 | M28: 43815 | N28: GLS | P28: PHUC THAI V.023S-2 | Q28: 43820 | S28: VN | T28: PNH02 | U28: PNH02 | V28: SISEZ | W28: NAPKIN TISSUE PAPER, TOILET TISSUE PAPER | X28: 12,337.80 | Y28: 12,440.80 | Z28: 11,145.11 | AA28: 10,527.11 | AB28: GAOU6131396-40HC | AC28: 20 ROLLS | AE28: 1 | AF28: - Reqeusted TP (PPAP-SISEZ): 23.12.019, Received (031/19): 23.12.2019 - Cleared Transit T671 (PPAP): 24.12.2019, delivered by PPAP and arrived at SISEZ: 25.12.2019 | AI28: =A28 -> 081 | AJ28: ..\2 BJC\081 GLSW951006
A29: 082 | B29: GLSW951005 | C29: 43813 | D29: IMPORT | E29: Sea | F29: BJC | G29: PPAP | H29: 20191210/VP-BJC-KH | I29: 20191210/VP-BJC-KH | J29: 43809 | K29: VN-KH 19/01/36193 | L29: 43816 | M29: 43815 | N29: GLS | P29: PHUC THAI V.023S-2 | Q29: 43820 | S29: VN | T29: PNH02 | U29: PNH02 | V29: SISEZ | W29: NAPKIN TISSUE PAPER | X29: 44,982.20 | Y29: 45,295.40 | Z29: 39,359.43 | AA29: 37,505.43 | AB29: GAOU6458033-40HC, CAIU8602367-40HC, CAIU8449577 -40HC | AC29: 108 ROLLS | AE29: 3 | AF29: - Reqeusted TP (PPAP-SISEZ): 23.12.019, Received (032/19): 23.12.2019 - Cleared Transit T673 (PPAP): 24.12.2019, delivered by PPAP and arrive at SISEZ: 25.12.2019 | AI29: =A29 -> 082 | AJ29: ..\2 BJC\082 GLSW951005
A30: 083 | B30: OMPLCHKHOMP004-20 | C30: 43842 | D30: IMPORT | E30: Sea | F30: BJC | G30: OMP | H30: 001/2020 | I30: 001/2020 | J30: 43839 | M30: 43845 | N30: OMP | P30: NP SAMUTSAKHON V.202S | Q30: 43844 | S30: TH | T30: SHV15 | U30: SHV15 | V30: SISEZ | W30: CARTON BOX, KRAFT PAPER | X30: 13,693.00 | Y30: 14,036.00 | Z30: 10,470.83 | AA30: 8,970.06 | AB30: OMPL9573568-40HC | AC30: 29 PALLETS | AE30: 1 | AF30: - Requested TP (OMP-SISEZ): 15.01.2020, Received (001/20): 15.01.2020 | AI30: =A30 -> 083 | AJ30: 001/20 | AL30: T1 | AM30: 43836
A31: 084 | B31: GLSN0040049 | C31: 43848 | D31: IMPORT | E31: Sea | F31: BJC | G31: PPAP | H31: 20200115/VP-BJC-KH | I31: 20200115/VP-BJC-KH | J31: 43845 | K31: VN-KH 20/01/02746 | L31: 43880 | M31: 43847 | N31: PPAP | Q31: 43855 | S31: VN | T31: PNH02 | U31: PNH02 | V31: SISEZ | W31: NAPKIN TISSUE PAPER, TOILET TISSUE PAPER | X31: 58,690.10 | Y31: 59,109.20 | Z31: 52,173.68 | AA31: 49,780.68 | AB31: SEGU5593865-40HC, GAOU6131992-40HC, GAOU6458603-40HC, DRYU9954580-40HC | AC31: 129 ROLLS | AE31: 4 | AF31: - Reqeusted TP (PPAP-SISEZ): 27.01.2020, Received (002/20): 27.01.2020 - Clearance Transit T66 (PPAP-SISEZ): 28.02.2020, Delivered by PPAP and arrived SISEZ: 29.01.2020 | AI31: =A31 -> 084 | AJ31: ..\2 BJC\084 GLSN0040049
A32: 085 | B32: OMPLCHKHOMP018-20 | C32: 43868 | D32: IMPORT | E32: Sea | F32: BJC | G32: OMP | H32: 003/2020 | I32: 003/2020 | J32: 43864 | M32: 43872 | N32: OMP | P32: NP SAMUTSAKHON V.206S | Q32: 43871 | S32: TH | T32: SHV15 | U32: SHV15 | V32: SISEZ | W32: CARTON BOX, PLASTIC WRAPPER | X32: 5,541.00 | Y32: 5,630.00 | Z32: 14,740.10 | AA32: 13,256.46 | AB32: OMPL9826075-40HC | AC32: 16 PALLETS | AE32: 1 | AF32: - Requested TP (OMP-SISEZ): 11.02.2020, Received (003/20): 12.02.2020 | AI32: =A32 -> 085
A33: 086 | B33: OMPLCHKHOMP019-20 | C33: 43868 | D33: IMPORT | E33: Sea | F33: BJC | G33: OMP | H33: 004/2020 | I33: 004/2020 | J33: 43864 | K33: D2020-0033433 | L33: 43872 | M33: 43872 | N33: OMP | P33: NP SAMUTSAKHON V.206S | Q33: 43871 | S33: TH | T33: SHV15 | U33: SHV15 | V33: SISEZ | W33: JUMBO ROLL TISSUE PAPER | X33: 8,701.00 | Y33: 9,001.00 | Z33: 11415.61 | AA33: 10390.76 | AB33: OMPL5578405-40HC | AC33: 120 ROLLS | AE33: 1 | AF33: - Requested TP (OMP-SISEZ): 11.02.2020, Received (004/20): 12.02.2020 | AG33: BERLI JUCKER | AI33: =A33 -> 086
A34: 087 | B34: GMD20HPHPNH0011 | C34: 43877 | D34: IMPORT | E34: Sea | F34: BJC | G34: PPAP | H34: 20200213/VP-BJC-KH | I34: 20200213/VP-BJC-KH | J34: 43874 | K34: VN-KH 20/01/05598 | L34: 43880 | M34: 43878 | N34: PPAP | P34: MEKONG02 V.156W | Q34: 43882 | S34: VN | T34: PNH02 | U34: PNH02 | V34: SISEZ | W34: NAPKIN TISSUE PAPER, TOILET TISSUE PAPER | X34: 57,891.60 | Y34: 58,310.70 | Z34: 51,467.27 | AA34: 49,075.27 | AB34: GMDU8181905-40HC, GMDU8188664-40HC, GMDU8181124-40HC, GMDU8180555-40HC | AC34: 129 ROLLS | AE34: 4 | AI34: 087
A35: 088 | B35: COSU4512576787 | C35: 43736 | D35: IMPORT | E35: Sea | F35: YAT SOVANN (FULL WELL) | G35: COSCO | M35: 43902 | N35: COSCO | P35: BRIDGE V.0100N | Q35: 43787 | S35: RU | T35: SHV01 | U35: SHV01 | V35: SIDP | W35: TOYOTA ALPHARD & MERCEDES-BENZ | Y35: 4,350.00 | AB35: CCLU7155182-40HC | AC35: 2 UNITS | AE35: 1
A36: 089 | B36: COSU6254749374 | C36: 43864 | D36: IMPORT | E36: Sea | F36: C.V.E.T | G36: (FULLWEL: Mr. KHEMARA) | M36: 43902 | N36: COSCO | P36: BRIDGE V.0118N | Q36: 43912 | S36: RU | T36: SHV01 | U36: SHV01 | V36: SIDP | W36: MERCEDES-BENZ | Y36: 4,370.00 | AB36: CBHU6302946-40HC | AC36: 2 UNITS | AE36: 1
A37: 090 | B37: OOLU2633339140 | C37: 43872 | D37: IMPORT | E37: Sea | F37: C.V.E.T | G37: (FULLWEL: Mr. KHEMARA) | M37: 43902 | N37: OOCL | S37: US | T37: SHV01 | U37: SHV01 | V37: SIDP | W37: USED ROLL ROYCE GHOST | Y37: 3,500.00 | AB37: CCLU9940780-45HC | AC37: 1 UNIT | AE37: 1
A38: 091 | B38: OMPLCHKHOMP029-20 | C38: 43902 | D38: IMPORT | E38: Sea | F38: BJC | G38: OMP | H38: 006/2020 | I38: 006/2020 | J38: 43895 | M38: 43902 | N38: OMP | P38: NP SAMUTSAKHON V.209S | S38: TH | T38: SHV15 | U38: SHV15 | V38: SISEZ | W38: CARTON BOX, PLASTIC WRAPPER, USED MACHINERY | X38: 8,218.00 | Y38: 8,335.00 | Z38: 21793.48 | AA38: 20307.17 | AB38: TTNU9896365-40HC | AC38: 17 PALLETS | AE38: 1 | AJ38: 006/20 | AL38: T4 | AM38: 43907
A39: 092 | B39: SHAWDO59954 | C39: 43900 | D39: IMPORT | E39: Sea | F39: TF MOTORS (CAMBODIA) CO., LTD | G39: SHENDA | H39: CAM20191205S2 | I39: CAM20191205S2 | J39: 43850 | K39: E201322602501007 | L39: 43901 | M39: 43910 | N39: IAL | P39: NEWPORT CYPRESS 79 V.044W | Q39: 43911 | S39: CN | T39: PNH02 | U39: PNH02 | V39: SIBW | W39: NEW CAR MG ZS | X39: 15,168.00 | Y39: 15,168.00 | Z39: 158400 | AA39: 156000 | AB39: CAIU9709690-40'HQ IAAU1695139-40'HQ IAAU1730857-40'HQ IAAU1773329-40'HQ | AC39: 12 UNITS | AD39: 0 | AE39: 4
A40: 093 | B40: GMD20HPHPNH0027 | C40: 43912 | D40: IMPORT | E40: Sea | F40: BJC | G40: GMD | H40: 20200318/VP-BJC-KH | I40: 20200318/VP-BJC-KH | J40: 43908 | K40: VN-KH 20/01/10323 | L40: 43915 | M40: 43916 | N40: GMD | S40: VN | T40: PNH02 | U40: PNH02 | V40: SI SEZ | W40: TOILET TISSUE PAPER, NAPKIN TISSUE PAPER | X40: 84,523.70.70 | Y40: 85,155.70 | Z40: 74653.48 | AA40: 71065.48 | AB40: GMDU8180534-40HC,GMDU8183791-40HC,GMDU8180663-40HC,GMDU8184587-40HC,GMDU8187673-40HC,GMDU8181525-40HC | AC40: 171 ROLLS | AE40: 6
...

Sheet DATA INF
O1: ADDRESS FOR REQUEST LETTER | S1: FOR AUT | AB1: [$-12000453] dddd mmmm yyyy | AC1: [@ប្រតិទិនចន្ទគតិ១] &[@ប្រតិទិនចន្ទគតិ២]&[@ប្រតិទិនចន្ទគតិ៣]&[@ប្រតិទិនចន្ទគតិ៤]&[@ប្រតិទិនចន្ទគតិ៥] | AD1: [$-12000453]dd ខែ mmmm ឆ្នាំ yyyy") | AE1: [$-km-KH,1200] dddd
A2: PORT | B2: 2 | C2: SR CODE | D2: LOCATION SR 2 | E2: LINK SR | F2: INF-M 1 | H2: CNEE | I2: PIC | J2: FOR CO CV | O2: ADD NEW CNEE | P2: HEADER | Q2: LOLO | S2: NAME | T2: ID CARD | U2: CNEE | V2: VAT | W2: TEL | X2: NAME SI | Y2: ID CARD SI | Z2: TEL | AB2: Date | AC2: ប្រតិទិនចន្ទគតិ2023 | AD2: ប្រតិទិនចន្ទគតិ១ | AE2: ប្រតិទិនចន្ទគតិ២ | AF2: ប្រតិទិនចន្ទគតិ៣ | AG2: ប្រតិទិនចន្ទគតិ៤ | AH2: ប្រតិទិនចន្ទគតិ៥ | AK2: លេខរៀងខែ/ស័ក | AL2: ចន្ទគតិ | AM2: សុរិយាគតិ | AN2: ស័ក
A3: POI01 | B3: ការិយាល័យគយ និងរដ្ឋាករមាត់ច្រកអន្តរជាតិប៉ោយប៉ែត | C3: HHA | D3: ហេង ហ៊ុយ (Heng Huy Autocars) ដែលមានអាស័យដ្ឋាន #ដីឡូត៍ ១៥០៦៧ ផ្លូវ១១៤ សង្កាត់មនោរម្យ ខណ្ឌ៧មករា រាជធានីភ្នំពេញ | F3: ង៉ូវ ចាន់រស្មី | H3: TF MOTORS (CAMBODIA) CO., LTD | I3: ង៉ូវ ចាន់រស្មី | J3: PNH02 | K3: មាត់ច្រកកំពង់ផែអន្តរជាតិភ្នំពេញ | M3: DON THONGPRAPAI | N3: កាន់លិខិតឆ្លងដែនលេខ: AB4555337 ទូរសព្ទ័លេខ 095 777 975 ជំនួសប្រធានក្រុមហ៊ុន SUVANNAPHUM INVESTMENT CO., LTD អត្តសញ្ញាណកម្មសារពើពន្ធ (VAT) លេខៈ L001-901801901 ជានីតិបុគ្គលជើងសារគយដែលមានរូបវន្តបុគ្គលជើងសាគយតំណាងលោក/លោកស្រី ផេង សុវណ្ណា អត្តសញ្ញាណប័ណ្ណសញ្ជាតិខ្មែរលេខៈ 190228973 ទូរសព្ទ័លេខ 012 333 901 ប័ណ្ណសម្គាល់ជើងសាគយលេខ #699B ផុតសុពលភាពថ្ងៃទី 31 ខែ ធ្នូ ឆ្នាំ 2024 ។ | O3: TF MOTORS (CAMBODIA) CO., LTD | P3: NO. 174-175 (BLOCK 1C, 1D AND 2C, 2D) OF CALIFORNIA HOUSE, RUSSIAN FEDERATION BLVD, SANGKAT TEUK THLA, PHNOM PENH, CAMBODIA VAT: L001-104008598, TEL: +855 888 772 209 | Q3: NO. 174-175 (BLOCK 1C, 1D AND 2C, 2D) OF CALIFORNIA HOUSE, RUSSIAN FEDERATION BLVD, SANGKAT TEUK THLA, PHNOM PENH, CAMBODIA VAT: L001-104008598, TEL: +855 888 772 209 | R3: POIPET | S3: MO GUANKANG | T3: EG7009964 | U3: HUAN YA HE ZHONG (CAMBODIA) TRADING CO., LTD | V3: L001-901908165 | W3: 017 555924 | AB3: 45658 | AC3: ថ្ងៃពុធ ៣កើត ខែបុស្ស ឆ្នាំរោង ឆស័ក ព.ស.២៥៦៨ | AD3: ថ្ងៃចន្ទ | AE3: ៥ រោច | AF3: ខែមិគសិរ | AG3: ឆ្នាំថោះ | AH3: បញ្ចស័ក ពស. ២៥៦៧ | AK3: 1 | AL3: មិគសិរ | AM3: មករា | AN3: ឯកស័ក | AP3: 1
A4: POI02 | B4: សាខាគយ និងរដ្ឋាករដូង | C4: MG | D4: MORRIS GARAGES ដែលមានអាសយដ្ឋាន #អគារ ១៧៤-១៧៥ (ប្លុក ១C, ១D និង ២C, ២D) នៃកាលីហ្វ័រញ៉ា សូសលហៅស៍ ផ្លូវ សហព័ន្ធរុស្ស៊ី សង្កាត់ទឹកថ្លា ខណ្ឌសែនសុខ រាជធានីភ្នំពេញ ជាទីតាំងបង្ហាញ (SHOWROOM)របស់ក្រុមហ៊ុន TF MOTORS (CAMBODIA) CO., LTD។ | E4: https://goo.gl/maps/WuC6bokrk32WsiPf6 | F4: លាង សុភា | G4: ភេទប្រុស មានអត្តសញ្ញាណប័ណ្ណសញ្ជាតិខ្មែរលេខៈ0107001600(01) មានតួនាទីជាបុគ្គលិកផ្នែករដ្ឋាបាល TF MOTORS (CAMBODIA) CO., LTD អត្តសញ្ញាណកម្មសារពើពន្ធ (VAT)លេខៈ L001-104008598 ទូរសព្ទ័លេខៈ 010 483 668 | H4: TF MOTORS (CAMBODIA) CO., LTD | I4: លាង សុភា | J4: SHV11 | K4: កំពង់ផែអន្តរជាតិក្រុងព្រះសីហនុ | M4: WICHAI ON-SRI | N4: កាន់លិខិតឆ្លងដែនលេខ: AD0667637 ទូរសព្ទ័លេខ 089 890 324 ជាប្រធានក្រុមហ៊ុន SUVANNAPHUM INVESTMENT CO., LTD អត្តសញ្ញាណកម្មសារពើពន្ធ (VAT) លេខៈ L001-901801901 ជានីតិបុគ្គលជើងសារគយដែលមានរូបវន្តបុគ្គលជើងសាគយតំណាងលោក/លោកស្រី ផេង សុវណ្ណា អត្តសញ្ញាណប័ណ្ណសញ្ជាតិខ្មែរលេខៈ 190228973 ទូរសព្ទ័លេខ 012 333 901 ប័ណ្ណសម្គាល់ជើងសាគយលេខ #699B ផុតសុពលភាពថ្ងៃទី 31 ខែ ធ្នូ ឆ្នាំ 2026 ។ | O4: DHONNA JIA CHENG IMP EXP CO., LTD. | P4: #255,ST.351,PHUM TA NGOV KROM,SANGKAT NIROTH, KHAN CHBAR AMPOV,PHNOM PENH, CAMBODIA VAT No : K007-901903553 | Q4: #255,ST.351,PHUM TA NGOV KROM,SANGKAT NIROTH, KHAN CHBAR AMPOV,PHNOM PENH, CAMBODIA VAT No : K007-901903553 | R4: DOUNG | S4: ហ៊ាន សហមុន្នី | T4: 70296574 | U4: ZENITH MACHINERY LEASING CO.,LTD | V4: K009-902005913 | W4: 070 673 598 | X4: WICHAI ON-SRI | Y4: AD0667637 | Z4: 089 890 324 | AB4: 45659 | AC4: ថ្ងៃព្រហស្បតិ៍ ៤កើត ខែបុស្ស ឆ្នាំរោង ឆស័ក ព.ស.២៥៦៨ | AD4: ថ្ងៃអង្គារ | AE4: ៦ រោច | AF4: ខែមិគសិរ | AG4: ឆ្នាំថោះ | AH4: បញ្ចស័ក ពស. ២៥៦៧ | AK4: 2 | AL4: បុស្ស | AM4: កុម្ភៈ | AN4: ទោស័ក | AP4: 1
A5: PNH02 | B5: សាខាគយ និងរដ្ឋាករកំពង់ផែអន្តរជាតិភ្នំពេញ | C5: SSK | D5: SIN SOKEN (ស៊ិន សុខកេន) ដែលមានអាសយដ្ឋានឃ្លាំងលេខ ៥៩៧ ផ្លូវមុន្នីវង្ស សង្កាត់បឹងព្រលឹត ខណ្ឌ៧មករា រាជធានីភ្នំពេញ ។ | F5: DON THONGPRAPAI | G5: កាន់លិខិតឆ្លងដែនលេខ: AB4555337 ទូរសព្ទ័លេខ 095 777 975 ជាប្រធានក្រុមហ៊ុន SUVANNAPHUM INVESTMENT CO., LTD អត្តសញ្ញាណកម្មសារពើពន្ធ (VAT) លេខៈ L001-901801901 ជានីតិបុគ្គលជើងសារគយដែលមានរូបវន្តបុគ្គលជើងសាគយតំណាងលោក/លោកស្រី ផេង សុវណ្ណា អត្តសញ្ញាណប័ណ្ណសញ្ជាតិខ្មែរលេខៈ 190228973 ទូរសព្ទ័លេខ 012 333 901 ប័ណ្ណសម្គាល់ជើងសាគយលេខ #699B ផុតសុពលភាពថ្ងៃទី 31 ខែ ធ្នូ ឆ្នាំ 2026 ។ | H5: HUAN YA HE ZHONG (CAMBODIA) TRADING CO., LTD | I5: MO GUANKANG | J5: SIBW | K5: បញ្ចេញទំនិញនៅមាត់ច្រកភណ្ឌាគារគយមានដែនកំណត់សុវណ្ណភូមិ | M5: BOONNAM KULRAKAMPUSIRI | N5: កាន់លិខិតឆ្លងដែនលេខ: AC2134008 ទូរសព្ទ័លេខ 069 777 815 ជាប្រធានក្រុមហ៊ុន SUVANNAPHUM INVESTMENT CO., LTD អត្តសញ្ញាណកម្មសារពើពន្ធ (VAT) លេខៈ L001-901801901 ជានីតិបុគ្គលជើងសារគយដែលមានរូបវន្តបុគ្គលជើងសាគយតំណាងលោក/លោកស្រី ផេង សុវណ្ណា អត្តសញ្ញាណប័ណ្ណសញ្ជាតិខ្មែរលេខៈ 190228973 ទូរសព្ទ័លេខ 012 333 901 ប័ណ្ណសម្គាល់ជើងសាគយលេខ #699B ផុតសុពលភាពថ្ងៃទី 31 ខែ ធ្នូ ឆ្នាំ 2026 ។ | O5: SREY CHINDA IMPORT EXPORT CO., LTD | P5: #23N, St.2007, SANGKAT KAKAB, KHAN PORSENCHEY, PHNOM PENH, CAMBODIA. VAT No : K010-901902352 | Q5: #23N, St.2007, SANGKAT KAKAB, KHAN PORSENCHEY, PHNOM PENH, CAMBODIA. VAT No : K010-901902352 | R5: PHNOM PENH | S5: ZHU SHUAI | T5: E24411836 | U5: MINGYANG GUOJI TRADING CO.,LTD | V5: L001-902001625 | W5: 018 9159555 | X5: BOONNAM KULRAKAMPUSIRI | Y5: AC2134008 | Z5: 069 777 815 | AB5: 45660 | AC5: ថ្ងៃសុក្រ ៥កើត ខែបុស្ស ឆ្នាំរោង ឆស័ក ព.ស.២៥៦៨ | AD5: ថ្ងៃពុធ | AE5: ៧ រោច | AF5: ខែមិគសិរ | AG5: ឆ្នាំថោះ | AH5: បញ្ចស័ក ពស. ២៥៦៧ | AK5: 3 | AL5: មាឃ | AM5: មីនា | AN5: ត្រីស័ក
A6: SHV11 | B6: សាខាគយ និងរដ្ឋាករកំពង់ផែអន្តរជាតិក្រុងព្រះសីហនុ | C6: V99 | D6: V99 PLATINUM AUTO ដែលមានអាសយដ្ឋានឃ្លាំងលេខ 31-32 ផ្លូវ114 សង្កាត់មនោរម្យ ខណ្ឌ៧មករា រាជធានីភ្នំពេញ​ | E6: https://goo.gl/maps/gSiPqu5BXT1h24HJ6 | F6: MO GUANKANG | G6: ភេទប្រុស ដែលមានលិខិតឆ្លងដែនលេខៈ EG7009964 ជាប្រធានក្រុមហ៊ុន HUAN YA HE ZHONG (CAMBODIA) TRADING CO., LTD អត្តសញ្ញាណកម្មសារពើពន្ធ (VAT)លេខៈ L001-901908165 ទូរសព្ទ័លេខៈ 017 555924 | H6: N/A | I6: MA YUANQIANG | J6: SIDP | K6: បញ្ចេញទំនិញនៅមាត់ច្រកផែស្ងួតសុវណ្ណភូមិ | M6: WONGMONGKOL SRESTTAWIN | N6: កាន់លិខិតឆ្លងដែនលេខ: AC5014016 ទូរសព្ទ័លេខ 093 544 566 ជាប្រធានក្រុមហ៊ុន SUVANNAPHUM INVESTMENT CO., LTD អត្តសញ្ញាណកម្មសារពើពន្ធ (VAT) លេខៈ L001-901801901 ជានីតិបុគ្គលជើងសារគយដែលមានរូបវន្តបុគ្គលជើងសាគយតំណាងលោក/លោកស្រី ផេង សុវណ្ណា អត្តសញ្ញាណប័ណ្ណសញ្ជាតិខ្មែរលេខៈ 190228973 ទូរសព្ទ័លេខ 012 333 901 ប័ណ្ណសម្គាល់ជើងសាគយលេខ #699B ផុតសុពលភាពថ្ងៃទី 31 ខែ ធ្នូ ឆ្នាំ 2026 ។ | O6: DOUNG PUM AGRI IMPORT & EXPORT CO,.LTD | P6: អាស័យដ្ឋាន#1FEo​ ផ្លូវ ៩៣ ភូមិ ផ្សារតូច សង្កាត់ ទួលសង្កែទី១ ខណ្ឌ ឫស្សីកែវ រាជធានីភ្នំពេញ VAT No : K008-902005660 | Q6: អាស័យដ្ឋាន#1FEo​ ផ្លូវ ៩៣ ភូមិ ផ្សារតូច សង្កាត់ ទួលសង្កែទី១ ខណ្ឌ ឫស្សីកែវ រាជធានីភ្នំពេញ VAT No : K008-902005660 | R6: SIHANOUKVILLE | S6: ទ្រី ស៊ាងហេង | T6: 250012059 | U6: TRY SEANGHENG TRADING CO., LTD | V6: B124-902102170 | W6: 096 9266789 | X6: WONGMONGKOL SRESTTAWIN | Y6: AC5014016 | Z6: 093 544 566 | AB6: 45661 | AC6: ថ្ងៃសៅរ៍ ៦កើត ខែបុស្ស ឆ្នាំរោង ឆស័ក ព.ស.២៥៦៨ | AD6: ថ្ងៃព្រហស្បតិ៍ | AE6: ៨ រោច | AF6: ខែមិគសិរ | AG6: ឆ្នាំថោះ | AH6: បញ្ចស័ក ពស. ២៥៦៧ | AK6: 4 | AL6: ផល្គុន | AM6: មេសា | AN6: ចត្វាស័ក
A7: BAV01 | B7: សាខាគយ​ និងរដ្ឋាករស្វាយរៀង ការិយាល័យគយ និងរដ្ឋាករបាវិត | C7: BYD | D7: ឈ្មោះ BYD Sale & Service Center ដែលមានអាស័យដ្ឋាន#52 ផ្លូវជាតិលេខ 6A ភូមិដើមគរ សង្កាត់ជ្រោយចង្វារ ខណ្ឌជ្រោយចង្វារ រាជធានីភ្នំពេញ ជាទីតាំងបង្ហាញរថយន្ត (Showroom) របស់ក្រុមហ៊ុន HUAN YA HE ZHONG (CAMBODIA) TRADING CO., LTD | E7: https://www.google.com/maps/place/BYD+Cambodia/@11.592152,104.9271733,17z/data=!3m1!4b1!4m5!3m4!1s0x310953d2e3fa102f:0x97e2f0815633bd99!8m2!3d11.592152!4d104.929362 | F7: MA YUANQIANG | H7: N/A | I7: TANG XIUNING | J7: SISEZ | K7: បញ្ចេញទំនិញនៅតំបន់សេដ្ឋកិច្ចពិសេសសុវណ្ណភូមិ | O7: JI SHUN DA TRADING CO., LTD | P7: #B75, ST.B, PHUM KBAL DAMREY I, SANGKAT KAKAB I, KHAN PORSENCHEY, PHNOM PENH, CAMBODIA VAT : K010-901908667 | Q7: #B75, ST.B, PHUM KBAL DAMREY I, SANGKAT KAKAB I, KHAN PORSENCHEY, PHNOM PENH, CAMBODIA VAT : K010-901908667 | R7: BAVET | S7: BOONNAM KULRAKAMPUSIRI | T7: AC2134008 | U7: BJC CELLOX(CAMBODIA) CO., LTD | V7: L001-901639149 | W7: 069 777 815 | AB7: 45662 | AC7: ថ្ងៃអាទិត្យ ៧កើត ខែបុស្ស ឆ្នាំរោង ឆស័ក ព.ស.២៥៦៨ | AD7: ថ្ងៃសុក្រ | AE7: ៩ រោច | AF7: ខែមិគសិរ | AG7: ឆ្នាំថោះ | AH7: បញ្ចស័ក ពស. ២៥៦៧ | AK7: 5 | AL7: ចេត្រ | AM7: ឧសភា | AN7: ឆស័ក
A8: AIR01 | B8: សាខាគយ និងរដ្ឋាករអាកាសយាន្ដដ្ឋានអន្តរជាតិភ្នំពេញ | C8: RATANNAK | D8: រតនៈ ឡាក់សិរី ខា ត្រេដ័រ (RATANAK LUXURY CAR TRADER) ដែលមានអាស័យដ្ឋានផ្ទះលេខ #639KR ផ្លូវ 93 មហាវិថីព្រះមុន្នីវង្ស ភូមិ 7 សង្កាត់បឹងកេងកងទី 3 ខណ្ឌចំការមន រាជធានីភ្នំពេញ ។ | E8: https://goo.gl/maps/bnuc2F89m9JhgRMW7 | F8: LIAO KAILING | G8: ភេទប្រុស ដែលមានលិខិតឆ្លងដែនលេខៈ EG2412090 ជាប្រធានក្រុមហ៊ុន ONEROAD INDUSTRIAL (CAMBODIA) CO.,LTD អត្តសញ្ញាណកម្មសារពើពន្ធ (VAT)លេខៈ K002-902101770 | H8: ONEROAD INDUSTRIAL (CAMBODIA) CO.,LTD | I8: LIAO KAILING | J8: PNH01 | K8: បញ្ចេញទំនិញនៅមាត់ច្រកអាកាសយាន្តដ្ឋានអន្តរជាតិភ្នំពេញ | O8: HUAN YA HE ZHONG (CAMBODIA) TRADING CO., LTD | P8: 52 NATIONAL ROAD NO 6A RUSSEY KEO PHNOM PENH Contact Person: Marco Mok VAT: L001-901908165 ,Tel: +853 2882 2822 | Q8: 52 NATIONAL ROAD NO 6A RUSSEY KEO PHNOM PENH Contact Person: Marco Mok VAT: L001-901908165 ,Tel: +853 2882 2822 | R8: PHNOM PENH AIRPORT | S8: WICHAI ON-SRI | T8: AD0667637 | U8: BJC CELLOX(CAMBODIA) CO., LTD | V8: L001-901639149 | W8: 089 890 324 | AB8: 45663 | AC8: ថ្ងៃចន្ទ ៨កើត ខែបុស្ស ឆ្នាំរោង ឆស័ក ព.ស.២៥៦៨ | AD8: ថ្ងៃសៅរ៍ | AE8: ១០ រោច | AF8: ខែមិគសិរ | AG8: ឆ្នាំថោះ | AH8: បញ្ចស័ក ពស. ២៥៦៧ | AK8: 6 | AL8: ពិសាខ | AM8: មិថុនា | AN8: អដ្ឋស័ក
A9: BMC11 | B9: ការិយាល័យគយ និងរដ្ឋាករមាត់ច្រកអន្តរជាតិប៉ោយប៉ែត | C9: ORG | D9: ONE ROAD GROUP ​ដែលមានអាស័យដ្ឋាន No.288K,Street 598,Sangkat Toul Sangke 2,Khan Reusey Keo,Phnom Penh, Cambodia។ | E9: https://maps.google.com/maps?q=11.604460,104.898928&ll=11.604460,104.898928&z=16 | F9: ZHANG HUA | G9: ភេទប្រុស ដែលមានលិខិតឆ្លងដែនលេខៈ E37888060 ជាប្រធានក្រុមហ៊ុន H U A Y (CAMBODIA) INTERNATIONAL AUTO TRADE CO., LTD អត្តសញ្ញាណកម្មសារពើពន្ធ (VAT)លេខៈ L001-901909613 ទូរសព្ទ័លេខៈ +855 098881618​ | H9: H U A Y (CAMBODIA) INTERNATIONAL AUTO TRADE CO., LTD | I9: ZHANG HUA | J9: PNH19 | K9: បញ្ចេញទំនិញនៅមាត់ច្រកផែស្ងួតតិចស្រ៊ុន | O9: SAN FENG JIAN ZHU CO.,LTD. | P9: #C២៧ បុរីអាការសចរណ៍ ផ្លូវ ភូមិក្បាលដំរី១ សង្កាត់កាកាបទី១ ខណ្ឌពោធិ៍សែនជ័យ រាជធានីភ្នំពេញ ​Vat No : K010-902000030 | Q9: #C២៧ បុរីអាការសចរណ៍ ផ្លូវ ភូមិក្បាលដំរី១ សង្កាត់កាកាបទី១ ខណ្ឌពោធិ៍សែនជ័យ រាជធានីភ្នំពេញ ​Vat No : K010-902000030 | R9: TEC SRUN DRYPORT | S9: លាង សុភា | T9: 0107001600(01) | U9: TF MOTORS (CAMBODIA) CO., LTD | V9: L001-104008598 | W9: 088 8772 209 | AB9: 45664 | AC9: ថ្ងៃអង្គារ ៩កើត ខែបុស្ស ឆ្នាំរោង ឆស័ក ព.ស.២៥៦៨ | AD9: ថ្ងៃអាទិត្យ | AE9: ១១ រោច | AF9: ខែមិគសិរ | AG9: ឆ្នាំថោះ | AH9: បញ្ចស័ក ពស. ២៥៦៧ | AK9: 7 | AL9: ជេស្ឋ | AM9: កក្កដា | AN9: នព្វស័ក
A10: PVG15 | B10: ការិយាល័យគយ និងរដ្ឋាករមាត់ច្រកអន្តរជាតិម៉ឺនជ័យ | C10: MYGT | D10: ឈ្មោះ មីងយ៉ាងគួជីត្រេឌីង ឯ.ក ដែលមានទីតាំងអាគារ 174K សង្កាត់ទួលសង្កែ ខណ្ឌប្ញស្សីកែវ រាជធានីភ្នំពេញ របស់ក្រុមហ៊ុន MINGYANG GUOJI TRADING CO., LTD។ | E10: https://goo.gl/maps/GsWi5kemXdEiPexB8 | F10: ពឹង បូរិន | G10: ភេទប្រុស ដែលមានលិខិតឆ្លងដែនលេខៈ 011248801 ជាប្រធានក្រុមហ៊ុន RECOVERY COLLECTION CONSULTANT CO.,LTD.​ អត្តសញ្ញាណកម្មសារពើពន្ធ (VAT)លេខៈ K009-901902489 ទូរសព្ទ័លេខៈ +85595 242 721 | H10: RECOVERY COLLECTION CONSULTANT CO.,LTD | I10: ពឹង បូរិន | O10: ONEROAD INDUSTRIAL (CAMBODIA) CO.,LTD | P10: #N-៤០ ផ្លូវNewton Koh Pich, Mulberry Park ភូមិ ៤ សង្កាត់ ទន្លេបាសាក់ ខណ្ឌ ចំការមន រាជធានីភ្នំពេញ VAT No : K002-902101770 | Q10: #N-៤០ ផ្លូវNewton Koh Pich, Mulberry Park ភូមិ ៤ សង្កាត់ ទន្លេបាសាក់ ខណ្ឌ ចំការមន រាជធានីភ្នំពេញ VAT No : K002-902101770 | S10: ZHOU YOUYUAN | T10: EJ6181097 | U10: XST AUTO (CAMBODIA) INTERNATIONAL TRADE CO.,LTD | V10: L001-902101200 | W10: 0967100000 | AB10: 45665 | AC10: ថ្ងៃពុធ ១០កើត ខែបុស្ស ឆ្នាំរោង ឆស័ក ព.ស.២៥៦៨ | AD10: ថ្ងៃចន្ទ | AE10: ១២ រោច | AF10: ខែមិគសិរ | AG10: ឆ្នាំថោះ | AH10: បញ្ចស័ក ពស. ២៥៦៧ | AK10: 8 | AL10: អាសាធ | AM10: សីហា | AN10: សំរឹទ្វិស័ក
A11: PNH01 | B11: សាខាគយ និងរដ្ឋាករ អាកាសយាន្តដ្ឋានអន្តរជាតិ | C11: SOUEAST | D11: SOUEAST (សោតអៀសអូតូខា) ដែលមានអាស័យដ្ឋាន No.21-23 street 214,Phnum 2,Sangkat Boeng Rang,Khan Daun Penh,Phnom Penh,Cambodia។ | E11: https://goo.gl/maps/2NmY7hFBS2k9oh8Y7 | F11: សុន ដារ៉ា | G11: ភេទប្រុស ដែលមានលិខិតឆ្លងដែនលេខៈ 061527309 ជាប្រធានក្រុមហ៊ុន SON DARA IMEX CO.,LTD. អត្តសញ្ញាណកម្មសារពើពន្ធ (VAT)លេខៈ K006-902005865 ទូរសព្ទ័លេខៈ +85592 731118 | H11: SON DARA IMEX CO.,LTD | I11: សុន ដារ៉ា | O11: MINGYANG GUOJI TRADING CO.,LTD | P11: 174K STREET 105 SANGKAT TUAL SANGKAT KHAN RUSSET KEO PHOM PENH,THE KINGDOM OF CAMBODIA TEL:+855 0189159555 | Q11: 174K STREET 105 SANGKAT TUAL SANGKAT KHAN RUSSET KEO PHOM PENH,THE KINGDOM OF CAMBODIA TEL:+855 0189159555 | S11: ង៉ូវ ចាន់រស្មី | T11: 061434557 | U11: TF MOTORS (CAMBODIA) CO., LTD | V11: L001-104008598 | W11: 088 8772209 | AB11: 45666 | AC11: ថ្ងៃព្រហស្បតិ៍ ១១កើត ខែបុស្ស ឆ្នាំរោង ឆស័ក ព.ស.២៥៦៨ | AD11: ថ្ងៃអង្គារ | AE11: ១៣ រោច | AF11: ខែមិគសិរ | AG11: ឆ្នាំថោះ | AH11: បញ្ចស័ក ពស. ២៥៦៧ | AK11: 9 | AL11: ស្រាពណ៍ | AM11: កញ្ញា
A12: PNH19 | B12: ការិយាល័យគយនិងរដ្ឋាករផែស្ងួត តិច ស្រ៊ុន | C12: UMG | D12: ឈ្មោះ យូណាយធីត មើឃ្យូរី គ្រុប ដែលមានទីតាំង No.287 ផ្លូវជាតិលេខ3 សង្កាត់ចោមចៅ1 ខណ្ឌពោធិ៍សែនជ័យ រាជធានីភ្នំពេញ របស់ក្រុមហ៊ុន UNITED MERCURY GROUP CO., LTD។ | E12: https://goo.gl/maps/SqAr2vWr8cFYvyLK6 | F12: WICHAI ON-SRI | G12: ភេទប្រុស ដែលមានលិខិតឆ្លងដែនលេខៈ AD0667637 ជំនួសប្រធានចាត់ការទូទៅក្រុមហ៊ុន SUVANNAPHUM INVESTMENT CO., LTD អត្តសញ្ញាណកម្មសារពើពន្ធ (VAT)លេខៈ L001-901801901 ទូរសព្ទ័លេខៈ 089 890 324 | H12: NAL SRUN 62 IMPORT EXPORT CO.,LTD. | I12: ស៊្រុន ណាល់ | O12: H U A Y (CAMBODIA) INTERNATIONAL AUTO TRADE CO., LTD | P12: អាស័យដ្ឋាន:# ៤៥ ផ្លូវសហព័ន្ធរុស្ស៊ី សង្កាត់ថ្លា ខណ្ឌសែនសុខ រាជធានីភ្នំពេញ ទូរស័ព្ទលេខ : +855 098881618​ ។ | Q12: អាស័យដ្ឋាន:# ៤៥ ផ្លូវសហព័ន្ធរុស្ស៊ី សង្កាត់ថ្លា ខណ្ឌសែនសុខ រាជធានីភ្នំពេញ ទូរស័ព្ទលេខ : +855 098881618​ ។ | S12: ZHANG HUA | T12: E37888060 | U12: A N D Y (CAMBODIA) INTERNATIONAL AUTO TRADE CO.,LTD | V12: L001-902104222 | W12: 098881618​ | AB12: 45667 | AC12: ថ្ងៃសុក្រ ១២កើត ខែបុស្ស ឆ្នាំរោង ឆស័ក ព.ស.២៥៦៨ | AD12: ថ្ងៃពុធ | AE12: ១៤ រោច | AF12: ខែមិគសិរ | AG12: ឆ្នាំថោះ | AH12: បញ្ចស័ក ពស. ២៥៦៧ | AK12: 10 | AL12: ភទ្របទ | AM12: តុលា
C13: FAW | D13: ឈ្មោះ FAW ដែលមានអាស័យដ្ឋាន: No.98 Street 110 , Toek Lok 1 Commune , Toul Kork District , Phnom Penh ទីតាំងបង្ហាញរថយន្ត (Showroom) របស់ក្រុមហ៊ុន VICTOR MOTOR CO.,LTD។ | E13: https://goo.gl/maps/ZEhCkybUEZNWhaRu9 | F13: ស៊្រុន ណាល់ | H13: TRY SEANGHENG TRADING CO.,LTD | I13: ទ្រី ស៊ាងហេង | O13: SON DARA IMEX CO.,LTD. | P13: #បុរីពិភពថ្មីចំការដូង ផ្ទះលេខ 95A ផ្លូវ 19 ភូមិប្រការ សង្កាត់ព្រៃស ខណ្ឌដង្កោ រាជធានីភ្នំពេញ Vat No : K006-902005865 | Q13: #បុរីពិភពថ្មីចំការដូង ផ្ទះលេខ 95A ផ្លូវ 19 ភូមិប្រការ សង្កាត់ព្រៃស ខណ្ឌដង្កោ រាជធានីភ្នំពេញ Vat No : K006-902005865 | S13: ហម គឹមឡេង | T13: 160322461 | U13: MAHA SOK APHIVATH TRADING CO.,LTD | V13: K006-902102027 | W13: 0974121521 | AB13: 45668 | AC13: ថ្ងៃសៅរ៍ ១៣កើត ខែបុស្ស ឆ្នាំរោង ឆស័ក ព.ស.២៥៦៨ | AD13: ថ្ងៃព្រហស្បតិ៍ | AE13: ១ កើត | AF13: ខែបុស្ស | AG13: ឆ្នាំថោះ | AH13: បញ្ចស័ក ពស. ២៥៦៧ | AK13: 11 | AL13: អស្សុជ | AM13: វិច្ឆិកា
C14: SODO HUAY | D14: ឈ្មោះ SOUEAST DONGFENG ដែលមានទីតាំងផ្ទះលេខ1076 ផ្លូវ2004 ភូមិទឹកថ្លា សង្កាត់ទឹកថ្លា ខណ្ឌសែនសុខ រាជធានីភ្នំពេញ ទីតាំងបង្ហាញរថយន្ត (Showroom) របស់ក្រុមហ៊ុន HUAY (CAMBODIA) INTERNATIONAL AUTO TRADE CO., LTD។ | E14: https://goo.gl/maps/ouoZkPz82XjHmWDGA | F14: ទ្រី ស៊ាងហេង | G14: ភេទប្រុស មានអត្តសញ្ញាណប័ណ្ណសញ្ជាតិខ្មែរលេខៈ 250012059 ជាប្រធានក្រុមហ៊ុន TRY SEANGHENG TRADING CO., LTD. អត្តសញ្ញាណកម្មសារពើពន្ធ (VAT)លេខៈ B124-902102170 ទូរសព្ទ័លេខៈ 0969266789 | H14: MILLION FARM AGRICULTURE CO.,LTD | I14: តាំង ហុង | O14: EVERSAILING SUPPLY CHAIN (CAMBODIA) CO.,LTD | P14: #១០G ផ្លូវ ២៣០ ភូមិ ៨ សង្កាត់ បឹងសាឡាង ខណ្ឌ ទួលគោក រាជធានីភ្នំពេញ Vat No : K005-902101776 | Q14: #១០G ផ្លូវ ២៣០ ភូមិ ៨ សង្កាត់ បឹងសាឡាង ខណ្ឌ ទួលគោក រាជធានីភ្នំពេញ Vat No : K005-902101776 | S14: MO GUANKANG | T14: EG7009964 | U14: HUAN YA HE ZHONG (CAMBODIA) TRADING CO., LTD | V14: L001-901908165 | W14: 017 555924 | AB14: 45669 | AC14: ថ្ងៃអាទិត្យ ១៤កើត ខែបុស្ស ឆ្នាំរោង ឆស័ក ព.ស.២៥៦៨ | AD14: ថ្ងៃសុក្រ | AE14: ២ កើត | AF14: ខែបុស្ស | AG14: ឆ្នាំថោះ | AH14: បញ្ចស័ក ពស. ២៥៦៧ | AK14: 12 | AL14: កត្តិក | AM14: ធ្នូ
C15: JMC AUTO | D15: ឈ្មោះ JMC AUTO ដែលមានអាស័យដ្ឋានផ្ទះលេខ #521, ផ្លូវជាតិលេខ 6A, ភូមិគៀនឃ្លាំង សង្កាត់ជ្រោយចង្វារ ខណ្ឌជ្រោយជង្វារ រាជធានីភ្នំពេញ ជាទីតាំងបង្ហាញរថយន្ត (Showroom) របស់ក្រុមហ៊ុន XST AUTO (CAMBODIA) INTERNATIONAL TRADE CO., LTD។ | E15: https://goo.gl/maps/AVkupG886tzbLokn9 | F15: តាំង ហុង | H15: XST AUTO (CAMBODIA) INTERNATIONAL TRADE CO.,LTD | I15: ZHOU YOUYUAN | O15: RECOVERY COLLECTION CONSULTANT CO.,LTD. | P15: ទីតាំងនៅផ្ទះ #C២៩ ផ្លូវ Maha-C ក្នុងបុរី មហាសែនសុខ ភូមិវិមានទ្រង់ សង្កាត់ក្រាំងធ្នង់ ខណ្ឌសែនសុខ រាជធានីភ្នំពេញ VAT: K009-901902489 | Q15: ទីតាំងនៅផ្ទះ #C២៩ ផ្លូវ Maha-C ក្នុងបុរី មហាសែនសុខ ភូមិវិមានទ្រង់ សង្កាត់ក្រាំងធ្នង់ ខណ្ឌសែនសុខ រាជធានីភ្នំពេញ VAT: K009-901902489 | S15: LI XINHUA | T15: E16409716 | U15: YUEKA ONE-STOP AUTO SERVICE CO. LTD | V15: L001-901804963 | W15: 078 890 777 | AB15: 45670 | AC15: ថ្ងៃចន្ទ ១៥កើត ខែបុស្ស ឆ្នាំរោង ឆស័ក ព.ស.២៥៦៨ | AD15: ថ្ងៃសៅរ៍ | AE15: ៣ កើត | AF15: ខែបុស្ស | AG15: ឆ្នាំថោះ | AH15: បញ្ចស័ក ពស. ២៥៦៧
C16: MUMG | D16: MATADOR UMG CAMBODIA ដែលមានអាស័យដ្ឋាន ស្ទឹងព្រែកត្នោត, ផ្លូវជាតិលេខ 4, ភូមិស្ទឹង ឃុំត្រពាំងគង ស្រុកសំរោងទង ខេត្តកំពង់ស្ពឺ។ | E16: https://goo.gl/maps/bnuc2F89m9JhgRMW7 | F16: ធន់ មករា | H16: FIR PLANNED CO.,LTD | I16: ខាន់ លីណា | O16: NAL SRUN 62 IMPORT EXPORT CO.,LTD. | P16: #២៣ ផ្លូវ២០ សង្កាត់ស្ទឹងមានជ័យទី៣ ខណ្ឌមានជ័យ រាជធានីភ្នំពេញ VAT: K007-9020022874 | Q16: #២៣ ផ្លូវ២០ សង្កាត់ស្ទឹងមានជ័យទី៣ ខណ្ឌមានជ័យ រាជធានីភ្នំពេញ VAT: K007-9020022874 | S16: គង់​ គិនណារី | T16: 010852466 | U16: AUTOMOTIVE ASIA (CAMBODIA) LIMITED | V16: L001-107030985 | W16: 023 222 204 | AB16: 45671 | AC16: ថ្ងៃអង្គារ ១រោច ខែបុស្ស ឆ្នាំរោង ឆស័ក ព.ស.២៥៦៨ | AD16: ថ្ងៃអាទិត្យ | AE16: ៤ កើត | AF16: ខែបុស្ស | AG16: ឆ្នាំថោះ | AH16: បញ្ចស័ក ពស. ២៥៦៧ | AK16: ១ រោច | AL16: ១ កើត
C17: FT | D17: ឈ្មោះ FORTHING ដែលមានទីតាំង #166 ផ្លូវជាតិលេខ 6 ភូមិគៀនឃ្លាំង សង្កាត់ជ្រោយចង្វារ ខណ្ឌជ្រោយចង្វារ រាជធានីភ្នំពេញ ជាទីតាំងបង្ហាញរថយន្ត (Showroom) របស់ក្រុមហ៊ុន YUEKA ONE-STOP AUTO SERVICE CO. LTD ទូរស័ព្ទលេខ: 087 866 762 ។ | E17: https://maps.app.goo.gl/WwG1EZtfFrMAoght5 | F17: ZHOU YOUYUAN | G17: ភេទប្រុស ដែលមានលិខិតឆ្លងដែនលេខៈ EJ6181097 ជាប្រធានក្រុមហ៊ុន XST AUTO (CAMBODIA) INTERNATIONAL TRADE CO.,LTD អត្តសញ្ញាណកម្មសារពើពន្ធ (VAT)លេខៈ L001-902101200 ទូរសព្ទ័លេខៈ 0967100000 | H17: UNITED MERCURY GROUP CO.,LTD | I17: ALFRED KASUMA ALIWARGA | O17: TRY SEANGHENG TRADING CO.,LTD | P17: ភូមិ ជើងឡង ឃុំ សួង ស្រុក សួង ខេត្ត ត្បូងឃ្មុំ VAT: B124-902102170 | Q17: ភូមិ ជើងឡង ឃុំ សួង ស្រុក សួង ខេត្ត ត្បូងឃ្មុំ VAT: B124-902102170 | S17: ស៊្រុន ណាល់ | T17: 061815277 | U17: NAL SRUN 62 IMPORT EXPORT CO.,LTD | V17: K007-902002874 | AB17: 45672 | AC17: ថ្ងៃពុធ ២រោច ខែបុស្ស ឆ្នាំរោង ឆស័ក ព.ស.២៥៦៨ | AD17: ថ្ងៃចន្ទ | AE17: ៥ កើត | AF17: ខែបុស្ស | AG17: ឆ្នាំថោះ | AH17: បញ្ចស័ក ពស. ២៥៦៧ | AK17: ២ រោច | AL17: ២ កើត
C18: MAX | D18: MAXUS ដែលមានអាសយដ្ឋាន #អគារ ១៧៤-១៧៥ (ប្លុក ១C, ១D និង ២C, ២D) នៃកាលីហ្វ័រញ៉ា សូសលហៅស៍ ផ្លូវ សហព័ន្ធរុស្ស៊ី សង្កាត់ទឹកថ្លា ខណ្ឌសែនសុខ រាជធានីភ្នំពេញ ជាទីតាំងបង្ហាញ (SHOWROOM)របស់ក្រុមហ៊ុន TF MOTORS (CAMBODIA) CO., LTD។ | E18: https://goo.gl/maps/WuC6bokrk32WsiPf6 | F18: ខាន់ លីណា | H18: MINGYANG GUOJI TRADING CO.,LTD | I18: ZHU SHUAI | O18: MILLION FARM AGRICULTURE CO.,LTD | P18: #Q២១ ជាន់ទី៣ ផ្លូវ Q ភូមិ ១៤ សង្កាត់ ទន្លេបាសាក់ ខណ្ឌ ចំការមន រាជធានីភ្នំពេញ VAT: K002-902102193 | Q18: #Q២១ ជាន់ទី៣ ផ្លូវ Q ភូមិ ១៤ សង្កាត់ ទន្លេបាសាក់ ខណ្ឌ ចំការមន រាជធានីភ្នំពេញ VAT: K002-902102193 | S18: YU YIXIANG | T18: EA3791641 | U18: VICTOR MOTOR CO.,LTD | V18: K005-901906510 | W18: 0968456666 | AB18: 45673 | AC18: ថ្ងៃព្រហស្បតិ៍ ៣រោច ខែបុស្ស ឆ្នាំរោង ឆស័ក ព.ស.២៥៦៨ | AD18: ថ្ងៃអង្គារ | AE18: ៦ កើត | AF18: ខែបុស្ស | AG18: ឆ្នាំថោះ | AH18: បញ្ចស័ក ពស. ២៥៦៧ | AK18: ៣ រោច | AL18: ៣ កើត
C19: SODO ANDY | D19: ឈ្មោះ SOUEAST DONGFENG ដែលមានទីតាំងផ្ទះលេខ1076 ផ្លូវ2004 ភូមិទឹកថ្លា សង្កាត់ទឹកថ្លា ខណ្ឌសែនសុខ រាជធានីភ្នំពេញ ទីតាំងបង្ហាញរថយន្ត (Showroom) របស់ក្រុមហ៊ុន A N D Y (CAMBODIA) INTERNATIONAL AUTO TRADE CO., LTD។ | E19: https://goo.gl/maps/ouoZkPz82XjHmWDGA | F19: ALFRED KASUMA ALIWARGA | G19: ភេទប្រុស ដែលមានលិខិតឆ្លងដែនលេខៈ C7615365 ជាប្រធានក្រុមហ៊ុន UNITED MERCURY GROUP CO.,LTD អត្តសញ្ញាណកម្មសារពើពន្ធ (VAT)លេខៈ L001-108001873 ទូរសព្ទ័លេខៈ 070 873235 | H19: SCD | I19: SREY CHINDA | O19: XST AUTO (CAMBODIA) INTERNATIONAL TRADE CO.,LTD | P19: #វិញ្ញាបនបត្រសម្គាល់ម្ចាស់អចលនវត្ថុលេខ ១២០៨០១០៤-០៥៥៨ ផ្លូវ ភូមិបាយ៉ាប សង្កាត់ភ្នំពេញថ្មី ខណ្ឌសែនសុខ រាជធានីភ្នំពេញ។ VAT: L001-902101200 | Q19: #វិញ្ញាបនបត្រសម្គាល់ម្ចាស់អចលនវត្ថុលេខ ១២០៨០១០៤-០៥៥៨ ផ្លូវ ភូមិបាយ៉ាប សង្កាត់ភ្នំពេញថ្មី ខណ្ឌសែនសុខ រាជធានីភ្នំពេញ។ VAT: L001-902101200 | S19: SAY SREYMOM | T19: 110597540 | U19: SAY SREYMOM IMPORT & EXPORT CO.,LTD | V19: K006-902106071 | W19: 011 303 425 | AB19: 45674 | AC19: ថ្ងៃសុក្រ ៤រោច ខែបុស្ស ឆ្នាំរោង ឆស័ក ព.ស.២៥៦៨ | AD19: ថ្ងៃពុធ | AE19: ៧ កើត | AF19: ខែបុស្ស | AG19: ឆ្នាំថោះ | AH19: បញ្ចស័ក ពស. ២៥៦៧ | AK19: ៤ រោច | AL19: ៤ កើត
C20: ATMT | D20: ឈ្មោះ Audi Phnom Penh ដែលមានអាសយដ្ឋាន#15Z ផ្លូវព្រះមុនីវង្ស កែងផ្លូវ 422 សង្កាត់ទន្លេបាសាក់ ខណ្ឌចំការមន រាជធានីភ្នំពេញ ទីតាំងបង្ហាញរថយន្ត (Showroom) របស់ក្រុមហ៊ុន AUTOMOTIVE ASIA (CAMBODIA) LIMITED។ | E20: https://maps.app.goo.gl/WDK2AHt4NY2gJxNs8 | F20: ZHU SHUAI | G20: ភេទស្រី ដែលមានលិខិតឆ្លងដែនលេខៈ E24411836 ជាប្រធានក្រុមហ៊ុន MINGYANG GUOJI TRADING CO., LTD អត្តសញ្ញាណកម្មសារពើពន្ធ (VAT)លេខៈ L001-1901801901​ | H20: TF MOTORS (CAMBODIA) CO., LTD | I20: ហូម៉េន សេនតូនី តាន់ឌីហ្សូណូ | O20: FIR PLANNED CO.,LTD | P20: ភូមិ អង្គសុគន្ធា ឃុំ មហាឫស្សី ស្រុក គងពិសី ខេត្ត កំពង់ស្ពឺ VAT: B105-901704100 | Q20: ភូមិ អង្គសុគន្ធា ឃុំ មហាឫស្សី ស្រុក គងពិសី ខេត្ត កំពង់ស្ពឺ VAT: B105-901704100 | S20: CHHOEM SAMBOK | T20: 030587652 | U20: AGRIMILE TRADING CO.,LTD | V20: K008-902103926 | W20: 017 537 443 | AB20: 45675 | AC20: ថ្ងៃសៅរ៍ ៥រោច ខែបុស្ស ឆ្នាំរោង ឆស័ក ព.ស.២៥៦៨ | AD20: ថ្ងៃព្រហស្បតិ៍ | AE20: ៨ កើត | AF20: ខែបុស្ស | AG20: ឆ្នាំថោះ | AH20: បញ្ចស័ក ពស. ២៥៦៧ | AK20: ៥ រោច | AL20: ៥ កើត
C21: CGC | D21: ឈ្មោះ ឆាយណាខា ដែលមានទីតាំងឃ្លាំងលេខ ៩-១០ ផ្លូវ ភូមិ ៧ សង្កាត់ ទឹកល្អក់ទី១ ខណ្ឌ ទួលគោក រាជធានីភ្នំពេញ ទីតាំងបង្ហាញរថយន្ត (Showroom) របស់ក្រុមហ៊ុន CHINA GOOD CAR INVESTMENT (CAMBODIA) CO.,LTD។ | E21: https://goo.gl/maps/TAd2yAmn6EJfHT3z8 | F21: SREY CHINDA | G21: ភេទស្រី មានអត្តសញ្ញាណប័ណ្ណសញ្ជាតិខ្មែរលេខៈ010432848(01) ជាប្រធានក្រុមហ៊ុន SREY CHINDA IMPORT EXPORT CO.,LTD អត្តសញ្ញាណកម្មសារពើពន្ធ (VAT)លេខៈ K010-901902352 ទូរសព្ទ័លេខៈ 098 700 350 | H21: VICTOR MOTOR CO.,LTD | I21: YU YIXIANG | O21: UNITED MERCURY GROUP CO.,LTD | P21: #៤៨ ផ្លូវ ជាតិលេខ៤ ភូមិ ព្រៃព្រីងខាងជើង សង្កាត់ ចោមចៅ ខណ្ឌ ពោធិ៍សែនជ័យ រាជធានីភ្នំពេញ VAT: L001-108001873 | Q21: #៤៨ ផ្លូវ ជាតិលេខ៤ ភូមិ ព្រៃព្រីងខាងជើង សង្កាត់ ចោមចៅ ខណ្ឌ ពោធិ៍សែនជ័យ រាជធានីភ្នំពេញ VAT: L001-108001873 | S21: PAIBOON LAOCHAN | T21: AB4916750 | U21: BJC CELLOX(CAMBODIA) CO., LTD | V21: L001-901639149 | W21: 092 784 079 | AB21: 45676 | AC21: ថ្ងៃអាទិត្យ ៦រោច ខែបុស្ស ឆ្នាំរោង ឆស័ក ព.ស.២៥៦៨ | AD21: ថ្ងៃសុក្រ | AE21: ៩ កើត | AF21: ខែបុស្ស | AG21: ឆ្នាំថោះ | AH21: បញ្ចស័ក ពស. ២៥៦៧ | AK21: ៦ រោច | AL21: ៦ កើត
C22: JETOUR | D22: ឈ្មោះ JETOUR ដែលមានទីតាំង#315,ផ្លូវជាតិ 6A,សង្កាត់ ព្រែកលៀប, ខណ្ឌ ជ្រោយចង្វារ, រាជធានីភ្នំពេញ ទីតាំងបង្ហាញរថយន្ត (Showroom) របស់ក្រុមហ៊ុន CHINA GOOD CAR INVESTMENT (CAMBODIA) CO.,LTD។ | E22: https://goo.gl/maps/z8V4So5cupHNnQ9f7 | F22: ហូម៉េន សេនតូនី តាន់ឌីហ្សូណូ | G22: ភេទប្រុស មានអត្តសញ្ញាណប័ណ្ណសញ្ជាតិខ្មែរលេខៈ010464617 ជាប្រធានក្រុមហ៊ុន TF MORTORS (CAMBODIA) CO.,LTD អត្តសញ្ញាណកម្មសារពើពន្ធ (VAT)លេខៈ L001-104008598 ទូរសព្ទ័លេខៈ 088 8772209 | H22: MOUSTAFA MT | I22: SET MOUSTAFA | O22: YUEKA ONE-STOP AUTO SERVICE CO. LTD | P22: 166#,NATIONAL ROAD NO.6, GROUP 4, PHUM KEAN KLAING, SANGKAT CHROY CHONG VA, KHAN CHROY CHONG VA, PHNOM PENH, CAMBODIA VAT: L001-901804963 | Q22: 166#,NATIONAL ROAD NO.6, GROUP 4, PHUM KEAN KLAING, SANGKAT CHROY CHONG VA, KHAN CHROY CHONG VA, PHNOM PENH, CAMBODIA VAT: L001-901804963 | S22: LIAO KAILING | T22: EG2412090 | U22: ONEROAD INDUSTRIAL (CAMBODIA) CO.,LTD | V22: K002-902101770 | AB22: 45677 | AC22: ថ្ងៃចន្ទ ៧រោច ខែបុស្ស ឆ្នាំរោង ឆស័ក ព.ស.២៥៦៨ | AD22: ថ្ងៃសៅរ៍ | AE22: ១០ កើត | AF22: ខែបុស្ស | AG22: ឆ្នាំថោះ | AH22: បញ្ចស័ក ពស. ២៥៦៧ | AK22: ៧ រោច | AL22: ៧ កើត
C23: DFSK | D23: ឈ្មោះ (DFSK) XST AUTO ដែលមានទីតាំង# 319,Hanoi Friendship Blvd（1019）សង្កាត់ភ្នំពេញថ្មី , ខណ្ឌសែនសុខ ,រាជធានីភ្នំពេញ ទីតាំងបង្ហាញរថយន្ត (Showroom) របស់ក្រុមហ៊ុន XST AUTO (CAMBODIA) INTERNATIONAL CO., LTD | E23: https://goo.gl/maps/xW9ZSXgkPh82TjKdA | F23: YU YIXIANG | G23: ភេទប្រុស ដែលមានលិខិតឆ្លងដែនលេខៈ EA3791641 ជាប្រធានក្រុមហ៊ុន VICTOR MOTOR CO.,LTD. អត្តសញ្ញាណកម្មសារពើពន្ធ (VAT)លេខៈ K005-901906510 ទូរសព្ទ័លេខៈ 099 255 500 | H23: JSD | I23: ហម គឹមឡេង | O23: VICTOR MOTOR CO.,LTD | P23: #៩៨ ផ្លូវ ១១០ សង្កាត់ ទឹកល្អក់ទី ១ ខណ្ឌ ទួលគោក រាជធានីភ្នំពេញ TEL: K005-901906510 | Q23: #៩៨ ផ្លូវ ១១០ សង្កាត់ ទឹកល្អក់ទី ១ ខណ្ឌ ទួលគោក រាជធានីភ្នំពេញ TEL: K005-901906510 | S23: ZHANG HUA | T23: E37888060 | U23: H U A Y (CAMBODIA) INTERNATIONAL AUTO TRADE CO., LTD | V23: L001-901909613 | W23: 098881618 | AB23: 45678 | AC23: ថ្ងៃអង្គារ ៨រោច ខែបុស្ស ឆ្នាំរោង ឆស័ក ព.ស.២៥៦៨ | AD23: ថ្ងៃអាទិត្យ | AE23: ១១ កើត | AF23: ខែបុស្ស | AG23: ឆ្នាំថោះ | AH23: បញ្ចស័ក ពស. ២៥៦៧ | AK23: ៨ រោច | AL23: ៨ កើត
C24: TUNING | D24: ឈ្មោះ AUTO TUNING ដែលមានទីតាំង NO 84-90, Street 214 Beoung Proluet, Khan 7 Meakara ទីតាំងបង្ហាញរថយន្ត (Showroom) របស់ក្រុមហ៊ុន O C D M TRADING CO., LTD ទូរស័ព្ទលេខ: 093 82 23 23។ | E24: https://goo.gl/maps/jLNButnqVMBP8jjv7 | F24: SET MOUSTAFA | G24: ភេទប្រុស ដែលមានលិខិតឆ្លងដែនលេខៈ 011053628 ជាប្រធានក្រុមហ៊ុន MOUSTAFA MT(CAMBODIA) CO.,LTD អត្តសញ្ញាណកម្មសារពើពន្ធ (VAT)លេខៈ K010-902103109 ទូរសព្ទ័លេខៈ 099 255 500 | H24: N/A | I24: WICHAI ON-SRI | O24: MAHA SOK APHIVATH TRADING CO.,LTD | P24: #បុរីពិភពថ្មីចំការដូងផ្ទះលេខ ០៦ ផ្លូវ ០៥ ភូមិ ប្រការ សង្កាត់ ព្រៃស ខណ្ឌ ដង្កោ រាជធានីភ្នំពេញ VAT: K006-902102027 | Q24: #បុរីពិភពថ្មីចំការដូងផ្ទះលេខ ០៦ ផ្លូវ ០៥ ភូមិ ប្រការ សង្កាត់ ព្រៃស ខណ្ឌ ដង្កោ រាជធានីភ្នំពេញ VAT: K006-902102027 | S24: PAV PHEA RUM | T24: 061675682 | U24: BURIRUM TECHNICIAN CO.,LTD | V24: K007-902201280 | W24: 012 400 152 | AB24: 45679 | AC24: ថ្ងៃពុធ ៩រោច ខែបុស្ស ឆ្នាំរោង ឆស័ក ព.ស.២៥៦៨ | AD24: ថ្ងៃចន្ទ | AE24: ១២ កើត | AF24: ខែបុស្ស | AG24: ឆ្នាំថោះ | AH24: បញ្ចស័ក ពស. ២៥៦៧ | AK24: ៩ រោច | AL24: ៩ កើត
C25: KIM SRUN | D25: ឈ្មោះ គឹមស្រ៊ុនព្រីមៀមអូតូ (KIM SRUN PREMIUM AUTO) ដែលមានទីតាំង អាគារ 168 មហាវិថីព្រះមុន្នីវង្ស (93),សង្កាត់ ស្រះចក,ខណ្ឌដូនពេញ រាជធានីភ្នំពេញ ទូរស័ព្ទលេខ 012 985 555។ | E25: 11.578325314877558, 104.91689997184871 | F25: ហម គឹមឡេង | H25: N/A | I25: DON THONGPRAPAI | O25: ZENITH MACHINERY LEASING CO., LTD | P25: #១៥H ផ្លូវបេតុង ភូមិទឹកថ្លា សង្កាត់ទឹកថ្លា ខណ្ឌសែនសុខ រាជធានីភ្នំពេញ VAT: K009-902005913 | Q25: #១៥H ផ្លូវបេតុង ភូមិទឹកថ្លា សង្កាត់ទឹកថ្លា ខណ្ឌសែនសុខ រាជធានីភ្នំពេញ VAT: K009-902005913 | S25: BAI JIUZHI | T25: EE3035125 | U25: CHINA GOOD CAR INVESTMENT (CAMBODIA) CO.,LTD | V25: K005-901907714 | W25: 092 778 859 | AB25: 45680 | AC25: ថ្ងៃព្រហស្បតិ៍ ១០រោច ខែបុស្ស ឆ្នាំរោង ឆស័ក ព.ស.២៥៦៨ | AD25: ថ្ងៃអង្គារ | AE25: ១៣ កើត | AF25: ខែបុស្ស | AG25: ឆ្នាំថោះ | AH25: បញ្ចស័ក ពស. ២៥៦៧ | AK25: ១០ រោច | AL25: ១០ កើត
C26: FAW-V | D26: ឈ្មោះ FAW-VOLKSWAGEN ដែលមានទីតាំងNo.98 Street 110 , Toek Lok 1 Commune , Toul Kork District , Phnom Penh ទីតាំងបង្ហាញរថយន្ត (Showroom) របស់ក្រុមហ៊ុន របស់ក្រុមហ៊ុន HS MOTOR CO.,LTD ទូរស័ព្ទលេខ:095 999 82។ | E26: https://goo.gl/maps/8kzFf2rzbnV62TrP9 | F26: BOONNAM KULRAKAMPUSIRI | G26: ភេទប្រុស ដែលមានលិខិតឆ្លងដែនលេខៈAC2134008 អគ្គនាយករងនៃក្រុមហ៊ុន BJC CELLOX(CAMBODIA) CO., LTD អត្តសញ្ញាណកម្មសារពើពន្ធ (VAT)លេខៈ L001-901639149 ទូរសព្ទ័លេខៈ 069 777 815 ទីតាំងនៅផ្លូវជាតិលេខ ១ គីឡូម៉ែតលេខ ៤៦ ភូមិ សំរោងក្អែរ ឃុំ សំរោងធំ ស្រុកកៀនស្វាយ ខេត្តកណ្តាល ។ | H26: N/A | I26: WICHAI ON-SRI | O26: A N D Y (CAMBODIA) INTERNATIONAL AUTO TRADE CO., LTD | P26: អាស័យដ្ឋាន:# ១០៧៦ ផ្លូវម៉ៃដា(២០០៤) ភូមិ ទឹកថ្លា សង្កាត់ ទឹកថ្លា ខណ្ឌសែនសុខ រាជធានីភ្នំពេញ VAT: L001-902104222 | Q26: អាស័យដ្ឋាន:# ១០៧៦ ផ្លូវម៉ៃដា(២០០៤) ភូមិ ទឹកថ្លា សង្កាត់ ទឹកថ្លា ខណ្ឌសែនសុខ រាជធានីភ្នំពេញ VAT: L001-902104222 | S26: CHOEM PICHIT | T26: 100746252 | U26: CHOEM PICHIT IMPORT EXPORT CO.,LTD | V26: L009-902202339 | W26: 093 453 081 | AB26: 45681 | AC26: ថ្ងៃសុក្រ ១១រោច ខែបុស្ស ឆ្នាំរោង ឆស័ក ព.ស.២៥៦៨ | AD26: ថ្ងៃពុធ | AE26: ១៤ កើត | AF26: ខែបុស្ស | AG26: ឆ្នាំថោះ | AH26: បញ្ចស័ក ពស. ២៥៦៧ | AK26: ១១ រោច | AL26: ១១ កើត
C27: GTV | D27: ឈ្មោះ GTV MOTOR ដែលមានអាស័យដ្ឋាន: National Road 2, Srok Thom Village, Cheung Keb Commune, Kandal Steung District, Kandal Province. Cambodia. ទីតាំងបង្ហាញរថយន្ត (Showroom) របស់ក្រុមហ៊ុន HS MOTOR CO.,LTD ទូរស័ព្ទលេខ:095 999 82។ | E27: https://goo.gl/maps/xjSR154zc2fC58Jp7 | F27: BAI JIUZHI | G27: ភេទប្រុស កាន់លិខិតឆ្លងដែនលេខ: EE3035125 ជាប្រធានក្រុមហ៊ុន CHINA GOOD CAR INVESTMENT (CAMBODIA) CO.,LTD អត្តសញ្ញាណកម្មសារពើពន្ធ (VAT)លេខៈ K005-901907714 ទូរសព្ទ័លេខៈ 092 778 859 | H27: CHINA GOOD CAR INVESTMENT (CAMBODIA) CO.,LTD | I27: BAI JIUZHI | O27: AUTOMOTIVE ASIA (CAMBODIA) LIMITED | P27: អាសយដ្ឋាន#15Z ផ្លូវព្រះមុនីវង្ស កែងផ្លូវ 422 សង្កាត់ទន្លេបាសាក់ ខណ្ឌចំការមន រាជធានីភ្នំពេញ VAT: L001-107030985 | Q27: អាសយដ្ឋាន#15Z ផ្លូវព្រះមុនីវង្ស កែងផ្លូវ 422 សង្កាត់ទន្លេបាសាក់ ខណ្ឌចំការមន រាជធានីភ្នំពេញ VAT: L001-107030985 | S27: JIANG ZHIPING | T27: E85954264 | U27: EVERSAILING SUPPLY CHAIN (CAMBODIA) CO.,LTD | V27: K005-902101776 | W27: 071 792 7651 | AB27: 45682 | AC27: ថ្ងៃសៅរ៍ ១២រោច ខែបុស្ស ឆ្នាំរោង ឆស័ក ព.ស.២៥៦៨ | AD27: ថ្ងៃព្រហស្បតិ៍ | AE27: ១៥ កើត | AF27: ខែបុស្ស | AG27: ឆ្នាំថោះ | AH27: បញ្ចស័ក ពស. ២៥៦៧ | AK27: ១២ រោច | AL27: ១២ កើត
C28: WUL | D28: ឈ្មោះ WULING ដែលមានទីតាំងលេខ ២៧៨H ផ្លូវជាតិលេខ៦អា ភូមិគៀនឃ្លាំង សង្កាត់ព្រែកលៀប ខណ្ឌជ្រោយចង្វារ រាជធានីភ្នំពេញ លេខទំនាក់ទំនង៖ 096 34 95 302 ជាទីតាំងបង្ហាញរថយន្ត (SHOWROOM) របស់ក្រុមហ៊ុន FD AUTO (CAMBODIA) INTERNATIONAL TRADE CO., LTD។ | E28: https://maps.app.goo.gl/8FzUWyHaxFMwdmLG8 | F28: ហ៊ាន សហមុន្នី | G28: ភេទប្រុស មានអត្តសញ្ញាណប័ណ្ណសញ្ជាតិខ្មែរលេខៈ 070296574 ជាប្រធានក្រុមហ៊ុន ZENITH MACHINERY LEASING CO.,LTD អត្តសញ្ញាណកម្មសារពើពន្ធ (VAT)លេខៈ K009-902005913 | H28: DHONNA JIA CHENG IMP EXP CO.,LTD | I28: សំ សុផល | O28: SAY SREYMOM IMPORT & EXPORT CO.,LTD | P28: អាសយដ្ឋាន#1A ផ្លូវ56D9 ភូមិម័ល សង្កាត់ដង្កោ ខណ្ឌដង្កោ រាជធានីភ្នំពេញ VAT: K006-902106071 | Q28: អាសយដ្ឋាន#1A ផ្លូវ56D9 ភូមិម័ល សង្កាត់ដង្កោ ខណ្ឌដង្កោ រាជធានីភ្នំពេញ VAT: K006-902106071 | S28: ALFRED KASUMA ALIWARGA | T28: C7615365 | U28: UNITED MERCURY GROUP CO.,LTD | V28: L001-108001873 | W28: 070 873235 | AB28: 45683 | AC28: ថ្ងៃអាទិត្យ ១៣រោច ខែបុស្ស ឆ្នាំរោង ឆស័ក ព.ស.២៥៦៨ | AD28: ថ្ងៃសុក្រ | AE28: ១ រោច | AF28: ខែបុស្ស | AG28: ឆ្នាំថោះ | AH28: បញ្ចស័ក ពស. ២៥៦៧ | AK28: ១៣ រោច | AL28: ១៣ កើត
C29: FAW TRUCKS | D29: ឈ្មោះ FAW TRUCKS ដែលមានអាស័យដ្ឋាន: No.51A ផ្លូវ ហាណូយ, ខណ្ឌសែនសុខ , រាជធានីភ្នំពេញ ទីតាំងបង្ហាញរថយន្ត (Showroom) របស់ក្រុមហ៊ុន JF MOTOR CO., LTD។ | E29: https://maps.app.goo.gl/2tvM1nyFbV613EuVA | F29: សំ សុផល | G29: ភេទស្រី មានអត្តសញ្ញាណប័ណ្ណសញ្ជាតិខ្មែរលេខៈ 061845188 ជាប្រធានក្រុមហ៊ុន DHONNA JIA CHENG IMP EXP CO.,LTD អត្តសញ្ញាណកម្មសារពើពន្ធ (VAT)លេខៈ K007-901903554 | H29: YUEKA ONE-STOP AUTO SERVICE CO. LTD | I29: LI XINHUA | O29: L U SEA TRADING SERVICE CO., LTD | P29: ផ្លូវជាតិលេខ៥ ភូមិដួង សង្កាត់ព្រែកព្នៅ ខណ្ឌរាជធានី ភ្នំពេញ VAT : K009-901905395 | Q29: ផ្លូវជាតិលេខ៥ ភូមិដួង សង្កាត់ព្រែកព្នៅ ខណ្ឌរាជធានី ភ្នំពេញ VAT : K009-901905395 | S29: OEURN CHANDET | T29: 150901855 | U29: O C D M TRADING CO., LTD | V29: K007-902104377 | W29: 011746031 | AB29: 45684 | AC29: ថ្ងៃចន្ទ ១៤រោច ខែបុស្ស ឆ្នាំរោង ឆស័ក ព.ស.២៥៦៨ | AD29: ថ្ងៃសៅរ៍ | AE29: ២ រោច | AF29: ខែបុស្ស | AG29: ឆ្នាំថោះ | AH29: បញ្ចស័ក ពស. ២៥៦៧ | AK29: ១៤ រោច | AL29: ១៤ កើត
C30: MG 60M | D30: MORRIS GARAGES ដែលមានទីតាំង #179-185 ផ្លូវ ឧកញ្ញ៉ាមហាភក្ដី ហ៊ុននាង, សង្កាត់ចាក់អង្រែក្រោម, ភ្នំពេញ ជាទីតាំងបង្ហាញ (SHOWROOM)របស់ក្រុមហ៊ុន TF MOTORS (CAMBODIA) CO., LTD។ | E30: https://maps.app.goo.gl/ABRHiNiopnSau79k7?g_st=ic | F30: LI XINHUA | G30: ភេទប្រុស ដែលមានលិខិតឆ្លងដែនលេខៈ E16409716 ជាប្រធានក្រុមហ៊ុន YUEKA ONE-STOP AUTO SERVICE CO. LTD អត្តសញ្ញាណកម្មសារពើពន្ធ (VAT)លេខៈ L001-901804963 ទូរសព្ទ័លេខៈ 078 890 777 | H30: ZENITH MACHINERY LEASING CO., LTD | I30: ហ៊ាន សហមុន្នី | O30: BURIRUM TECHNICIAN CO., LTD | P30: #C-09 និង C-10 ផ្លូវ លំ ភូមិ ដំណាក់ធំ សង្កាត់ ស្ទឹងមានជ័យទី២ ខណ្ឌ មានជ័យ រាជធានីភ្នំពេញ VAT : K007-902201280 | Q30: #C-09 និង C-10 ផ្លូវ លំ ភូមិ ដំណាក់ធំ សង្កាត់ ស្ទឹងមានជ័យទី២ ខណ្ឌ មានជ័យ រាជធានីភ្នំពេញ VAT : K007-902201280 | S30: DEAB SIYET | T30: 030598691 | U30: HUA RONG SENG INTERNATIONAL MINING CO.,LTD | V30: K009-902204536 | W30: 097 7978 632 | AB30: 45685 | AC30: ថ្ងៃអង្គារ ១៥រោច ខែបុស្ស ឆ្នាំរោង ឆស័ក ព.ស.២៥៦៨ | AD30: ថ្ងៃអាទិត្យ | AE30: ៣ រោច | AF30: ខែបុស្ស | AG30: ឆ្នាំថោះ | AH30: បញ្ចស័ក ពស. ២៥៦៧ | AK30: ១៥ រោច | AL30: ១៥ កើត
C31: MG SR | D31: MORRIS GARAGES ដែលមានទីតាំង #ផ្លូវ ភូមិ គោកត្នោត ឃុំ កណ្ដែក ស្រុក ប្រាសាទបាគង ខេត្តសៀមរាប ជាទីតាំងបង្ហាញ (SHOWROOM)របស់ក្រុមហ៊ុន TF MOTORS (CAMBODIA) CO., LTD។ | E31: https://maps.app.goo.gl/qWxmFSEBYSm1igPZ6?g_st=ic | F31: អូច ពៅ | G31: ភេទប្រុស មានអត្តសញ្ញាណប័ណ្ណសញ្ជាតិខ្មែរលេខៈ 051559119 ជាប្រធានក្រុមហ៊ុន DGML IMPORT EXPORT CO.,LTD អត្តសញ្ញាណកម្មសារពើពន្ធ (VAT)លេខៈ K006-902105683 | H31: BJC CELLOX (CAMBODIA) CO., LTD | I31: BOONNAM KULRAKAMPUSIRI | O31: CHINA GOOD CAR INVESTMENT (CAMBODIA) CO.,LTD | P31: #ឃ្លាំងលេខ ៩-១០ ផ្លូវ ភូមិ ៧ សង្កាត់ ទឹកល្អក់ទី១ ខណ្ឌ ទួលគោក រាជធានីភ្នំពេញ VAT : K005-901907714 | Q31: #ឃ្លាំងលេខ ៩-១០ ផ្លូវ ភូមិ ៧ សង្កាត់ ទឹកល្អក់ទី១ ខណ្ឌ ទួលគោក រាជធានីភ្នំពេញ VAT : K005-901907714 | S31: SORN HORNG | T31: 101205869 | U31: SORN HORNG ENTERPRISE CO.,LTD | V31: K010 902204642 | W31: 096 291 7646 | AB31: 45686 | AC31: ថ្ងៃពុធ ១កើត ខែមាឃ ឆ្នាំរោង ឆស័ក ព.ស.២៥៦៨ | AD31: ថ្ងៃចន្ទ | AE31: ៤ រោច | AF31: ខែបុស្ស | AG31: ឆ្នាំថោះ | AH31: បញ្ចស័ក ពស. ២៥៦៧
C32: AUTOHOME | D32: AUTOHOME ដែលមានអាសយដ្ឋាន #៨៥៦ ផ្លូវ សហព័ន្ធរុស្សី (១១០), ក្រុមទី៥ ភូមិ ទឹកថ្លា សង្កាត់ ទឹកថ្លា ខណ្ឌ សែនសុខ , ភ្នំពេញ ជាទីតាំងបង្ហាញ (SHOWROOM)របស់ក្រុមហ៊ុន AUTOHOME(CAMBODIA) IMPORT EXPORT CO.,LTD។ | E32: https://maps.app.goo.gl/2AHTffvCQvkcsz717?g_st=iw | F32: ជួន រ៉ូ | G32: ភេទប្រុស មានអត្តសញ្ញាណប័ណ្ណសញ្ជាតិខ្មែរលេខៈ 040430759 ជាប្រធានក្រុមហ៊ុន FEEDS UP CO.,LTD អត្តសញ្ញាណកម្មសារពើពន្ធ (VAT)លេខៈ K006-902105453 | H32: AUTOMOTIVE ASIA (CAMBODIA) LIMITED | I32: គង់​ គិនណារី | O32: CHOEM PICHIT IMPORT EXPORT CO.,LTD | P32: #គ្មាន ផ្លូវ ឩកញ៉ាម៉ុងឫទ្ធី(១៩២៨) ភូមិ ច្រេស សង្កាត់ គោកឃ្លាង ខណ្ឌ សែនសុខ រាជធានីភ្នំពេញ VAT : L009-902202339 | Q32: #គ្មាន ផ្លូវ ឩកញ៉ាម៉ុងឫទ្ធី(១៩២៨) ភូមិ ច្រេស សង្កាត់ គោកឃ្លាង ខណ្ឌ សែនសុខ រាជធានីភ្នំពេញ VAT : L009-902202339 | S32: DO MARYNOEL | T32: 011199507 | U32: HS MOTOR CO.,LTD | V32: K005 902205145 | W32: 015 707 091 | AB32: 45687 | AC32: ថ្ងៃព្រហស្បតិ៍ ២កើត ខែមាឃ ឆ្នាំរោង ឆស័ក ព.ស.២៥៦៨ | AD32: ថ្ងៃអង្គារ | AE32: ៥ រោច | AF32: ខែបុស្ស | AG32: ឆ្នាំថោះ | AH32: បញ្ចស័ក ពស. ២៥៦៧
C33: KAUTO | D33: ឈ្មោះ ខេអូតូ(K AUTO) ដែលមានទីតាំង អាគារ 168 មហាវិថីព្រះមុន្នីវង្ស (93),សង្កាត់ ស្រះចក,ខណ្ឌដូនពេញ រាជធានីភ្នំពេញ ទូរស័ព្ទលេខ 012 985 555។ | E33: 11.578325314877558, 104.91689997184871 | F33: គង់​ គិនណារី | G33: ភេទស្រី មានអត្តសញ្ញាណប័ណ្ណសញ្ជាតិខ្មែរលេខៈ010852466 មានតួនាទី ប្រធានក្រុមហ៊ុន AUTOMOTIVE ASIA (CAMBODIA) LIMITED អត្តសញ្ញាណកម្មសារពើពន្ធ (VAT)លេខៈ L001-107030985 | H33: N/A | I33: ស្រ៊ុន ណាល់ | O33: EVERSAILING SUPPLY CHAIN (CAMBODIA) CO.,LTD | P33: N0.10G,ST230 PHUM4 SANGKAT BOE UNG SALANG KHAN TUOL KOUK - PHNOM PENH VAT :K005-902101776 | Q33: N0.10G,ST230 PHUM4 SANGKAT BOE UNG SALANG KHAN TUOL KOUK - PHNOM PENH VAT :K005-902101776 | S33: CHENG JIUSI | T33: EE1326007 | U33: GTV MOTOR CO.,LTD | V33: L001-902203582 | W33: 015 707 091 | AB33: 45688 | AC33: ថ្ងៃសុក្រ ៣កើត ខែមាឃ ឆ្នាំរោង ឆស័ក ព.ស.២៥៦៨ | AD33: ថ្ងៃពុធ | AE33: ៦ រោច | AF33: ខែបុស្ស | AG33: ឆ្នាំថោះ | AH33: បញ្ចស័ក ពស. ២៥៦៧
